Workbook

Sheet 00_機關清冊
A1: 📌 機關清冊
A2: 機關代碼 | B2: 機關名稱 | C2: 備註 | D2: 建立日期
A3: A001 | B3: 人事處
A4: A002 | B4: 會計處
A5: A003 | B5: 政風處
A6: A004 | B6: 總務處
A7: A005 | B7: 資訊處
A8: A006 | B8: 法制處
A9: A007 | B9: 秘書處
A10: A008 | B10: 公關室
A11: B001 | B11: 第一組
A12: B002 | B12: 第二組
A13: B003 | B13: 第三組
A14: B004 | B14: 第四組
... A58: G008 | B58: 城區辦公室

Sheet 01_異動主檔
A1: 📝 異動主檔（請在此新增資料）
A2: 流水號 | B2: 年度 | C2: 修正日期 | D2: 機關名稱 | E2: 調整類型 | F2: 人數 | G2: 事由 | H2: 備註
A3: 💡 提示：「調整類型」請從下拉選單選擇｜「年度」請輸入民國年｜「機關名稱」請從下拉選單選擇
A4: 1 | B4: 99 | C4: 99/01 | D4: 人事處 | E4: 移入 | F4: 5 | G4: 業務調整
A5: 2 | B5: 99 | C5: 99/03 | D5: 人事處 | E5: 移出 | F5: 2 | G5: 屆齡退休
A6: 3 | B6: 99 | C6: 99/06 | D6: 第一組 | E6: 新增 | F6: 3 | G6: 編制調整 | H6: 新增一個科室
A7: 4 | B7: 99 | C7: 99/09 | D7: 台北分局 | E7: 移入 | F7: 4 | G7: 業務移撥
A8: 5 | B8: 100 | C8: 100/02 | D8: 人事處 | E8: 移入 | F8: 2 | G8: 考試分發
A9: 6 | B9: 100 | C9: 100/05 | D9: 會計處 | E9: 減列 | F9: 1 | G9: 組織精簡
A10: 7 | B10: 100 | C10: 100/08 | D10: 第二組 | E10: 移出 | F10: 3 | G10: 業務移撥 | H10: 調至其他單位
A11: 8 | B11: 101 | C11: 101/03 | D11: 人事處 | E11: 精簡 | F11: 2 | G11: 優退
A12: 9 | B12: 101 | C12: 101/07 | D12: 新北分局 | E12: 新增 | F12: 5 | G12: 新設置 | H12: 新增分局
A13: 10 | B13: 102 | C13: 102/01 | D13: 政風處 | E13: 移入 | F13: 3 | G13: 業務調整
A14: 11 | B14: 103 | C14: 103/04 | D14: 第一組 | E14: 移出 | F14: 1 | G14: 屆齡退休
A15: 12 | B15: 104 | C15: 104/06 | D15: 人事處 | E15: 新增 | F15: 4 | G15: 編制調整 | H15: 業務擴張
A16: 13 | B16: 105 | C16: 105/02 | D16: 台北分局 | E16: 減列 | F16: 2 | G16: 組織整併

Sheet 02_年初員額設定
A1: 📊 年初員額設定（99年度請手動輸入，100年度起自動帶入）
A2: ※ 黃色格子=需手動輸入｜綠色格子=公式自動計算（請勿修改）｜年份橫排，機關縱排
A4: 機關代碼 | B4: 機關名稱 | C4: 99年 | D4: 100年 | E4: 101年 | F4: 102年 | G4: 103年 | H4: 104年 | I4: 105年 | J4: 106年 | K4: 107年 | L4: 108年 | M4: 109年 | N4: 110年 | O4: 111年 | P4: 112年 | Q4: 113年 | R4: 114年 | S4: 115年 | T4: 116年 | U4: 117年 | V4: 118年 | W4: 119年 | X4: 120年 | Y4: 121年 | Z4: 122年 | AA4: 123年 | AB4: 124年 | AC4: 125年
A5: A001 | B5: 人事處 | C5: 50
A6: A002 | B6: 會計處 | C6: 53
A7: A003 | B7: 政風處 | C7: 56
A8: A004 | B8: 總務處 | C8: 59
A9: A005 | B9: 資訊處 | C9: 62
A10: A006 | B10: 法制處 | C10: 65
A11: A007 | B11: 秘書處 | C11: 68
A12: A008 | B12: 公關室 | C12: 71
A13: B001 | B13: 第一組 | C13: 74
A14: B002 | B14: 第二組 | C14: 77
A15: B003 | B15: 第三組 | C15: 80
A16: B004 | B16: 第四組 | C16: 83
... A19: B007 | B19: 第七組 | C19: 92
A20: B008 | B20: 第八組
A21: C001 | B21: 台北分局
A22: C002 | B22: 新北分局
A23: C003 | B23: 桃園分局
A24: C004 | B24: 台中分局
A25: C005 | B25: 台南分局
A26: C006 | B26: 高雄分局
A27: C007 | B27: 基隆分局
A28: C008 | B28: 花蓮分局
A29: D001 | B29: 綜合規劃科
A30: D002 | B30: 歲計科
A31: D003 | B31: 統計科
... A60: G008 | B60: 城區辦公室

Sheet 03_年度彙總
A1: 📈 年度彙總（自動計算，請勿直接修改）
A2: ※ 自動彙總「01_異動主檔」的資料｜本表為唯讀，資料有誤請回「01_異動主檔」修改
A4: 機關代碼 | B4: 機關名稱 | C4: 年度 | D4: 年初 | E4: 移入 | F4: 移出 | G4: 新增 | H4: 減列 | I4: 精簡 | J4: 年底
A5: A001 | B5: 人事處 | C5: 99 | D5: ='02_年初員額設定'!C5 | E5: =SUMIFS('01_異動主檔'!$F:$F,'01_異動主檔'!$B:$B,99,'01_異動主檔'!$D:$D,B5,'01_異動主檔'!$E:$E,"移入") | F5: =-SUMIFS('01_異動主檔'!$F:$F,'01_異動主檔'!$B:$B,99,'01_異動主檔'!$D:$D,B5,'01_異動主檔'!$E:$E,"移出") | G5: =SUMIFS('01_異動主檔'!$F:$F,'01_異動主檔'!$B:$B,99,'01_異動主檔'!$D:$D,B5,'01_異動主檔'!$E:$E,"新增") | H5: =-SUMIFS('01_異動主檔'!$F:$F,'01_異動主檔'!$B:$B,99,'01_異動主檔'!$D:$D,B5,'01_異動主檔'!$E:$E,"減列") | I5: =-SUMIFS('01_異動主檔'!$F:$F,'01_異動主檔'!$B:$B,99,'01_異動主檔'!$D:$D,B5,'01_異動主檔'!$E:$E,"精簡") | J5: =D5+E5+F5+G5+H5+I5
A6: A001 | B6: 人事處 | C6: 100 | D6: =J5 | E6: =SUMIFS('01_異動主檔'!$F:$F,'01_異動主檔'!$B:$B,100,'01_異動主檔'!$D:$D,B6,'01_異動主檔'!$E:$E,"移入") | F6: =-SUMIFS('01_異動主檔'!$F:$F,'01_異動主檔'!$B:$B,100,'01_異動主檔'!$D:$D,B6,'01_異動主檔'!$E:$E,"移出") | G6: =SUMIFS('01_異動主檔'!$F:$F,'01_異動主檔'!$B:$B,100,'01_異動主檔'!$D:$D,B6,'01_異動主檔'!$E:$E,"新增") | H6: =-SUMIFS('01_異動主檔'!$F:$F,'01_異動主檔'!$B:$B,100,'01_異動主檔'!$D:$D,B6,'01_異動主檔'!$E:$E,"減列") | I6: =-SUMIFS('01_異動主檔'!$F:$F,'01_異動主檔'!$B:$B,100,'01_異動主檔'!$D:$D,B6,'01_異動主檔'!$E:$E,"精簡") | J6: =D6+E6+F6+G6+H6+I6
A7: A001 | B7: 人事處 | C7: 101 | D7: =J6 | E7: =SUMIFS('01_異動主檔'!$F:$F,'01_異動主檔'!$B:$B,101,'01_異動主檔'!$D:$D,B7,'01_異動主檔'!$E:$E,"移入") | F7: =-SUMIFS('01_異動主檔'!$F:$F,'01_異動主檔'!$B:$B,101,'01_異動主檔'!$D:$D,B7,'01_異動主檔'!$E:$E,"移出") | G7: =SUMIFS('01_異動主檔'!$F:$F,'01_異動主檔'!$B:$B,101,'01_異動主檔'!$D:$D,B7,'01_異動主檔'!$E:$E,"新增") | H7: =-SUMIFS('01_異動主檔'!$F:$F,'01_異動主檔'!$B:$B,101,'01_異動主檔'!$D:$D,B7,'01_異動主檔'!$E:$E,"減列") | I7: =-SUMIFS('01_異動主檔'!$F:$F,'01_異動主檔'!$B:$B,101,'01_異動主檔'!$D:$D,B7,'01_異動主檔'!$E:$E,"精簡") | J7: =D7+E7+F7+G7+H7+I7
A8: A001 | B8: 人事處 | C8: 102 | D8: =J7 | E8: =SUMIFS('01_異動主檔'!$F:$F,'01_異動主檔'!$B:$B,102,'01_異動主檔'!$D:$D,B8,'01_異動主檔'!$E:$E,"移入") | F8: =-SUMIFS('01_異動主檔'!$F:$F,'01_異動主檔'!$B:$B,102,'01_異動主檔'!$D:$D,B8,'01_異動主檔'!$E:$E,"移出") | G8: =SUMIFS('01_異動主檔'!$F:$F,'01_異動主檔'!$B:$B,102,'01_異動主檔'!$D:$D,B8,'01_異動主檔'!$E:$E,"新增") | H8: =-SUMIFS('01_異動主檔'!$F:$F,'01_異動主檔'!$B:$B,102,'01_異動主檔'!$D:$D,B8,'01_異動主檔'!$E:$E,"減列") | I8: =-SUMIFS('01_異動主檔'!$F:$F,'01_異動主檔'!$B:$B,102,'01_異動主檔'!$D:$D,B8,'01_異動主檔'!$E:$E,"精簡") | J8: =D8+E8+F8+G8+H8+I8
A9: A001 | B9: 人事處 | C9: 103 | D9: =J8 | E9: =SUMIFS('01_異動主檔'!$F:$F,'01_異動主檔'!$B:$B,103,'01_異動主檔'!$D:$D,B9,'01_異動主檔'!$E:$E,"移入") | F9: =-SUMIFS('01_異動主檔'!$F:$F,'01_異動主檔'!$B:$B,103,'01_異動主檔'!$D:$D,B9,'01_異動主檔'!$E:$E,"移出") | G9: =SUMIFS('01_異動主檔'!$F:$F,'01_異動主檔'!$B:$B,103,'01_異動主檔'!$D:$D,B9,'01_異動主檔'!$E:$E,"新增") | H9: =-SUMIFS('01_異動主檔'!$F:$F,'01_異動主檔'!$B:$B,103,'01_異動主檔'!$D:$D,B9,'01_異動主檔'!$E:$E,"減列") | I9: =-SUMIFS('01_異動主檔'!$F:$F,'01_異動主檔'!$B:$B,103,'01_異動主檔'!$D:$D,B9,'01_異動主檔'!$E:$E,"精簡") | J9: =D9+E9+F9+G9+H9+I9
A10: A001 | B10: 人事處 | C10: 104 | D10: =J9 | E10: =SUMIFS('01_異動主檔'!$F:$F,'01_異動主檔'!$B:$B,104,'01_異動主檔'!$D:$D,B10,'01_異動主檔'!$E:$E,"移入") | F10: =-SUMIFS('01_異動主檔'!$F:$F,'01_異動主檔'!$B:$B,104,'01_異動主檔'!$D:$D,B10,'01_異動主檔'!$E:$E,"移出") | G10: =SUMIFS('01_異動主檔'!$F:$F,'01_異動主檔'!$B:$B,104,'01_異動主檔'!$D:$D,B10,'01_異動主檔'!$E:$E,"新增") | H10: =-SUMIFS('01_異動主檔'!$F:$F,'01_異動主檔'!$B:$B,104,'01_異動主檔'!$D:$D,B10,'01_異動主檔'!$E:$E,"減列") | I10: =-SUMIFS('01_異動主檔'!$F:$F,'01_異動主檔'!$B:$B,104,'01_異動主檔'!$D:$D,B10,'01_異動主檔'!$E:$E,"精簡") | J10: =D10+E10+F10+G10+H10+I10
A11: A001 | B11: 人事處 | C11: 105 | D11: =J10 | E11: =SUMIFS('01_異動主檔'!$F:$F,'01_異動主檔'!$B:$B,105,'01_異動主檔'!$D:$D,B11,'01_異動主檔'!$E:$E,"移入") | F11: =-SUMIFS('01_異動主檔'!$F:$F,'01_異動主檔'!$B:$B,105,'01_異動主檔'!$D:$D,B11,'01_異動主檔'!$E:$E,"移出") | G11: =SUMIFS('01_異動主檔'!$F:$F,'01_異動主檔'!$B:$B,105,'01_異動主檔'!$D:$D,B11,'01_異動主檔'!$E:$E,"新增") | H11: =-SUMIFS('01_異動主檔'!$F:$F,'01_異動主檔'!$B:$B,105,'01_異動主檔'!$D:$D,B11,'01_異動主檔'!$E:$E,"減列") | I11: =-SUMIFS('01_異動主檔'!$F:$F,'01_異動主檔'!$B:$B,105,'01_異動主檔'!$D:$D,B11,'01_異動主檔'!$E:$E,"精簡") | J11: =D11+E11+F11+G11+H11+I11
A12: A001 | B12: 人事處 | C12: 106 | D12: =J11 | E12: =SUMIFS('01_異動主檔'!$F:$F,'01_異動主檔'!$B:$B,106,'01_異動主檔'!$D:$D,B12,'01_異動主檔'!$E:$E,"移入") | F12: =-SUMIFS('01_異動主檔'!$F:$F,'01_異動主檔'!$B:$B,106,'01_異動主檔'!$D:$D,B12,'01_異動主檔'!$E:$E,"移出") | G12: =SUMIFS('01_異動主檔'!$F:$F,'01_異動主檔'!$B:$B,106,'01_異動主檔'!$D:$D,B12,'01_異動主檔'!$E:$E,"新增") | H12: =-SUMIFS('01_異動主檔'!$F:$F,'01_異動主檔'!$B:$B,106,'01_異動主檔'!$D:$D,B12,'01_異動主檔'!$E:$E,"減列") | I12: =-SUMIFS('01_異動主檔'!$F:$F,'01_異動主檔'!$B:$B,106,'01_異動主檔'!$D:$D,B12,'01_異動主檔'!$E:$E,"精簡") | J12: =D12+E12+F12+G12+H12+I12
A13: A001 | B13: 人事處 | C13: 107 | D13: =J12 | E13: =SUMIFS('01_異動主檔'!$F:$F,'01_異動主檔'!$B:$B,107,'01_異動主檔'!$D:$D,B13,'01_異動主檔'!$E:$E,"移入") | F13: =-SUMIFS('01_異動主檔'!$F:$F,'01_異動主檔'!$B:$B,107,'01_異動主檔'!$D:$D,B13,'01_異動主檔'!$E:$E,"移出") | G13: =SUMIFS('01_異動主檔'!$F:$F,'01_異動主檔'!$B:$B,107,'01_異動主檔'!$D:$D,B13,'01_異動主檔'!$E:$E,"新增") | H13: =-SUMIFS('01_異動主檔'!$F:$F,'01_異動主檔'!$B:$B,107,'01_異動主檔'!$D:$D,B13,'01_異動主檔'!$E:$E,"減列") | I13: =-SUMIFS('01_異動主檔'!$F:$F,'01_異動主檔'!$B:$B,107,'01_異動主檔'!$D:$D,B13,'01_異動主檔'!$E:$E,"精簡") | J13: =D13+E13+F13+G13+H13+I13
A14: A001 | B14: 人事處 | C14: 108 | D14: =J13 | E14: =SUMIFS('01_異動主檔'!$F:$F,'01_異動主檔'!$B:$B,108,'01_異動主檔'!$D:$D,B14,'01_異動主檔'!$E:$E,"移入") | F14: =-SUMIFS('01_異動主檔'!$F:$F,'01_異動主檔'!$B:$B,108,'01_異動主檔'!$D:$D,B14,'01_異動主檔'!$E:$E,"移出") | G14: =SUMIFS('01_異動主檔'!$F:$F,'01_異動主檔'!$B:$B,108,'01_異動主檔'!$D:$D,B14,'01_異動主檔'!$E:$E,"新增") | H14: =-SUMIFS('01_異動主檔'!$F:$F,'01_異動主檔'!$B:$B,108,'01_異動主檔'!$D:$D,B14,'01_異動主檔'!$E:$E,"減列") | I14: =-SUMIFS('01_異動主檔'!$F:$F,'01_異動主檔'!$B:$B,108,'01_異動主檔'!$D:$D,B14,'01_異動主檔'!$E:$E,"精簡") | J14: =D14+E14+F14+G14+H14+I14
A15: A001 | B15: 人事處 | C15: 109 | D15: =J14 | E15: =SUMIFS('01_異動主檔'!$F:$F,'01_異動主檔'!$B:$B,109,'01_異動主檔'!$D:$D,B15,'01_異動主檔'!$E:$E,"移入") | F15: =-SUMIFS('01_異動主檔'!$F:$F,'01_異動主檔'!$B:$B,109,'01_異動主檔'!$D:$D,B15,'01_異動主檔'!$E:$E,"移出") | G15: =SUMIFS('01_異動主檔'!$F:$F,'01_異動主檔'!$B:$B,109,'01_異動主檔'!$D:$D,B15,'01_異動主檔'!$E:$E,"新增") | H15: =-SUMIFS('01_異動主檔'!$F:$F,'01_異動主檔'!$B:$B,109,'01_異動主檔'!$D:$D,B15,'01_異動主檔'!$E:$E,"減列") | I15: =-SUMIFS('01_異動主檔'!$F:$F,'01_異動主檔'!$B:$B,109,'01_異動主檔'!$D:$D,B15,'01_異動主檔'!$E:$E,"精簡") | J15: =D15+E15+F15+G15+H15+I15
A16: A001 | B16: 人事處 | C16: 110 | D16: =J15 | E16: =SUMIFS('01_異動主檔'!$F:$F,'01_異動主檔'!$B:$B,110,'01_異動主檔'!$D:$D,B16,'01_異動主檔'!$E:$E,"移入") | F16: =-SUMIFS('01_異動主檔'!$F:$F,'01_異動主檔'!$B:$B,110,'01_異動主檔'!$D:$D,B16,'01_異動主檔'!$E:$E,"移出") | G16: =SUMIFS('01_異動主檔'!$F:$F,'01_異動主檔'!$B:$B,110,'01_異動主檔'!$D:$D,B16,'01_異動主檔'!$E:$E,"新增") | H16: =-SUMIFS('01_異動主檔'!$F:$F,'01_異動主檔'!$B:$B,110,'01_異動主檔'!$D:$D,B16,'01_異動主檔'!$E:$E,"減列") | I16: =-SUMIFS('01_異動主檔'!$F:$F,'01_異動主檔'!$B:$B,110,'01_異動主檔'!$D:$D,B16,'01_異動主檔'!$E:$E,"精簡") | J16: =D16+E16+F16+G16+H16+I16
A17: A001 | B17: 人事處 | C17: 111 | D17: =J16 | E17: =SUMIFS('01_異動主檔'!$F:$F,'01_異動主檔'!$B:$B,111,'01_異動主檔'!$D:$D,B17,'01_異動主檔'!$E:$E,"移入") | F17: =-SUMIFS('01_異動主檔'!$F:$F,'01_異動主檔'!$B:$B,111,'01_異動主檔'!$D:$D,B17,'01_異動主檔'!$E:$E,"移出") | G17: =SUMIFS('01_異動主檔'!$F:$F,'01_異動主檔'!$B:$B,111,'01_異動主檔'!$D:$D,B17,'01_異動主檔'!$E:$E,"新增") | H17: =-SUMIFS('01_異動主檔'!$F:$F,'01_異動主檔'!$B:$B,111,'01_異動主檔'!$D:$D,B17,'01_異動主檔'!$E:$E,"減列") | I17: =-SUMIFS('01_異動主檔'!$F:$F,'01_異動主檔'!$B:$B,111,'01_異動主檔'!$D:$D,B17,'01_異動主檔'!$E:$E,"精簡") | J17: =D17+E17+F17+G17+H17+I17
A18: A001 | B18: 人事處 | C18: 112 | D18: =J17 | E18: =SUMIFS('01_異動主檔'!$F:$F,'01_異動主檔'!$B:$B,112,'01_異動主檔'!$D:$D,B18,'01_異動主檔'!$E:$E,"移入") | F18: =-SUMIFS('01_異動主檔'!$F:$F,'01_異動主檔'!$B:$B,112,'01_異動主檔'!$D:$D,B18,'01_異動主檔'!$E:$E,"移出") | G18: =SUMIFS('01_異動主檔'!$F:$F,'01_異動主檔'!$B:$B,112,'01_異動主檔'!$D:$D,B18,'01_異動主檔'!$E:$E,"新增") | H18: =-SUMIFS('01_異動主檔'!$F:$F,'01_異動主檔'!$B:$B,112,'01_異動主檔'!$D:$D,B18,'01_異動主檔'!$E:$E,"減列") | I18: =-SUMIFS('01_異動主檔'!$F:$F,'01_異動主檔'!$B:$B,112,'01_異動主檔'!$D:$D,B18,'01_異動主檔'!$E:$E,"精簡") | J18: =D18+E18+F18+G18+H18+I18
A19: A001 | B19: 人事處 | C19: 113 | D19: =J18 | E19: =SUMIFS('01_異動主檔'!$F:$F,'01_異動主檔'!$B:$B,113,'01_異動主檔'!$D:$D,B19,'01_異動主檔'!$E:$E,"移入") | F19: =-SUMIFS('01_異動主檔'!$F:$F,'01_異動主檔'!$B:$B,113,'01_異動主檔'!$D:$D,B19,'01_異動主檔'!$E:$E,"移出") | G19: =SUMIFS('01_異動主檔'!$F:$F,'01_異動主檔'!$B:$B,113,'01_異動主檔'!$D:$D,B19,'01_異動主檔'!$E:$E,"新增") | H19: =-SUMIFS('01_異動主檔'!$F:$F,'01_異動主檔'!$B:$B,113,'01_異動主檔'!$D:$D,B19,'01_異動主檔'!$E:$E,"減列") | I19: =-SUMIFS('01_異動主檔'!$F:$F,'01_異動主檔'!$B:$B,113,'01_異動主檔'!$D:$D,B19,'01_異動主檔'!$E:$E,"精簡") | J19: =D19+E19+F19+G19+H19+I19
A20: A001 | B20: 人事處 | C20: 114 | D20: =J19 | E20: =SUMIFS('01_異動主檔'!$F:$F,'01_異動主檔'!$B:$B,114,'01_異動主檔'!$D:$D,B20,'01_異動主檔'!$E:$E,"移入") | F20: =-SUMIFS('01_異動主檔'!$F:$F,'01_異動主檔'!$B:$B,114,'01_異動主檔'!$D:$D,B20,'01_異動主檔'!$E:$E,"移出") | G20: =SUMIFS('01_異動主檔'!$F:$F,'01_異動主檔'!$B:$B,114,'01_異動主檔'!$D:$D,B20,'01_異動主檔'!$E:$E,"新增") | H20: =-SUMIFS('01_異動主檔'!$F:$F,'01_異動主檔'!$B:$B,114,'01_異動主檔'!$D:$D,B20,'01_異動主檔'!$E:$E,"減列") | I20: =-SUMIFS('01_異動主檔'!$F:$F,'01_異動主檔'!$B:$B,114,'01_異動主檔'!$D:$D,B20,'01_異動主檔'!$E:$E,"精簡") | J20: =D20+E20+F20+G20+H20+I20
A21: A001 | B21: 人事處 | C21: 115 | D21: =J20 | E21: =SUMIFS('01_異動主檔'!$F:$F,'01_異動主檔'!$B:$B,115,'01_異動主檔'!$D:$D,B21,'01_異動主檔'!$E:$E,"移入") | F21: =-SUMIFS('01_異動主檔'!$F:$F,'01_異動主檔'!$B:$B,115,'01_異動主檔'!$D:$D,B21,'01_異動主檔'!$E:$E,"移出") | G21: =SUMIFS('01_異動主檔'!$F:$F,'01_異動主檔'!$B:$B,115,'01_異動主檔'!$D:$D,B21,'01_異動主檔'!$E:$E,"新增") | H21: =-SUMIFS('01_異動主檔'!$F:$F,'01_異動主檔'!$B:$B,115,'01_異動主檔'!$D:$D,B21,'01_異動主檔'!$E:$E,"減列") | I21: =-SUMIFS('01_異動主檔'!$F:$F,'01_異動主檔'!$B:$B,115,'01_異動主檔'!$D:$D,B21,'01_異動主檔'!$E:$E,"精簡") | J21: =D21+E21+F21+G21+H21+I21
A22: A001 | B22: 人事處 | C22: 116 | D22: =J21 | E22: =SUMIFS('01_異動主檔'!$F:$F,'01_異動主檔'!$B:$B,116,'01_異動主檔'!$D:$D,B22,'01_異動主檔'!$E:$E,"移入") | F22: =-SUMIFS('01_異動主檔'!$F:$F,'01_異動主檔'!$B:$B,116,'01_異動主檔'!$D:$D,B22,'01_異動主檔'!$E:$E,"移出") | G22: =SUMIFS('01_異動主檔'!$F:$F,'01_異動主檔'!$B:$B,116,'01_異動主檔'!$D:$D,B22,'01_異動主檔'!$E:$E,"新增") | H22: =-SUMIFS('01_異動主檔'!$F:$F,'01_異動主檔'!$B:$B,116,'01_異動主檔'!$D:$D,B22,'01_異動主檔'!$E:$E,"減列") | I22: =-SUMIFS('01_異動主檔'!$F:$F,'01_異動主檔'!$B:$B,116,'01_異動主檔'!$D:$D,B22,'01_異動主檔'!$E:$E,"精簡") | J22: =D22+E22+F22+G22+H22+I22
A23: A001 | B23: 人事處 | C23: 117 | D23: =J22 | E23: =SUMIFS('01_異動主檔'!$F:$F,'01_異動主檔'!$B:$B,117,'01_異動主檔'!$D:$D,B23,'01_異動主檔'!$E:$E,"移入") | F23: =-SUMIFS('01_異動主檔'!$F:$F,'01_異動主檔'!$B:$B,117,'01_異動主檔'!$D:$D,B23,'01_異動主檔'!$E:$E,"移出") | G23: =SUMIFS('01_異動主檔'!$F:$F,'01_異動主檔'!$B:$B,117,'01_異動主檔'!$D:$D,B23,'01_異動主檔'!$E:$E,"新增") | H23: =-SUMIFS('01_異動主檔'!$F:$F,'01_異動主檔'!$B:$B,117,'01_異動主檔'!$D:$D,B23,'01_異動主檔'!$E:$E,"減列") | I23: =-SUMIFS('01_異動主檔'!$F:$F,'01_異動主檔'!$B:$B,117,'01_異動主檔'!$D:$D,B23,'01_異動主檔'!$E:$E,"精簡") | J23: =D23+E23+F23+G23+H23+I23
A24: A001 | B24: 人事處 | C24: 118 | D24: =J23 | E24: =SUMIFS('01_異動主檔'!$F:$F,'01_異動主檔'!$B:$B,118,'01_異動主檔'!$D:$D,B24,'01_異動主檔'!$E:$E,"移入") | F24: =-SUMIFS('01_異動主檔'!$F:$F,'01_異動主檔'!$B:$B,118,'01_異動主檔'!$D:$D,B24,'01_異動主檔'!$E:$E,"移出") | G24: =SUMIFS('01_異動主檔'!$F:$F,'01_異動主檔'!$B:$B,118,'01_異動主檔'!$D:$D,B24,'01_異動主檔'!$E:$E,"新增") | H24: =-SUMIFS('01_異動主檔'!$F:$F,'01_異動主檔'!$B:$B,118,'01_異動主檔'!$D:$D,B24,'01_異動主檔'!$E:$E,"減列") | I24: =-SUMIFS('01_異動主檔'!$F:$F,'01_異動主檔'!$B:$B,118,'01_異動主檔'!$D:$D,B24,'01_異動主檔'!$E:$E,"精簡") | J24: =D24+E24+F24+G24+H24+I24
A25: A001 | B25: 人事處 | C25: 119 | D25: =J24 | E25: =SUMIFS('01_異動主檔'!$F:$F,'01_異動主檔'!$B:$B,119,'01_異動主檔'!$D:$D,B25,'01_異動主檔'!$E:$E,"移入") | F25: =-SUMIFS('01_異動主檔'!$F:$F,'01_異動主檔'!$B:$B,119,'01_異動主檔'!$D:$D,B25,'01_異動主檔'!$E:$E,"移出") | G25: =SUMIFS('01_異動主檔'!$F:$F,'01_異動主檔'!$B:$B,119,'01_異動主檔'!$D:$D,B25,'01_異動主檔'!$E:$E,"新增") | H25: =-SUMIFS('01_異動主檔'!$F:$F,'01_異動主檔'!$B:$B,119,'01_異動主檔'!$D:$D,B25,'01_異動主檔'!$E:$E,"減列") | I25: =-SUMIFS('01_異動主檔'!$F:$F,'01_異動主檔'!$B:$B,119,'01_異動主檔'!$D:$D,B25,'01_異動主檔'!$E:$E,"精簡") | J25: =D25+E25+F25+G25+H25+I25
A26: A001 | B26: 人事處 | C26: 120 | D26: =J25 | E26: =SUMIFS('01_異動主檔'!$F:$F,'01_異動主檔'!$B:$B,120,'01_異動主檔'!$D:$D,B26,'01_異動主檔'!$E:$E,"移入") | F26: =-SUMIFS('01_異動主檔'!$F:$F,'01_異動主檔'!$B:$B,120,'01_異動主檔'!$D:$D,B26,'01_異動主檔'!$E:$E,"移出") | G26: =SUMIFS('01_異動主檔'!$F:$F,'01_異動主檔'!$B:$B,120,'01_異動主檔'!$D:$D,B26,'01_異動主檔'!$E:$E,"新增") | H26: =-SUMIFS('01_異動主檔'!$F:$F,'01_異動主檔'!$B:$B,120,'01_異動主檔'!$D:$D,B26,'01_異動主檔'!$E:$E,"減列") | I26: =-SUMIFS('01_異動主檔'!$F:$F,'01_異動主檔'!$B:$B,120,'01_異動主檔'!$D:$D,B26,'01_異動主檔'!$E:$E,"精簡") | J26: =D26+E26+F26+G26+H26+I26
A27: A001 | B27: 人事處 | C27: 121 | D27: =J26 | E27: =SUMIFS('01_異動主檔'!$F:$F,'01_異動主檔'!$B:$B,121,'01_異動主檔'!$D:$D,B27,'01_異動主檔'!$E:$E,"移入") | F27: =-SUMIFS('01_異動主檔'!$F:$F,'01_異動主檔'!$B:$B,121,'01_異動主檔'!$D:$D,B27,'01_異動主檔'!$E:$E,"移出") | G27: =SUMIFS('01_異動主檔'!$F:$F,'01_異動主檔'!$B:$B,121,'01_異動主檔'!$D:$D,B27,'01_異動主檔'!$E:$E,"新增") | H27: =-SUMIFS('01_異動主檔'!$F:$F,'01_異動主檔'!$B:$B,121,'01_異動主檔'!$D:$D,B27,'01_異動主檔'!$E:$E,"減列") | I27: =-SUMIFS('01_異動主檔'!$F:$F,'01_異動主檔'!$B:$B,121,'01_異動主檔'!$D:$D,B27,'01_異動主檔'!$E:$E,"精簡") | J27: =D27+E27+F27+G27+H27+I27
A28: A001 | B28: 人事處 | C28: 122 | D28: =J27 | E28: =SUMIFS('01_異動主檔'!$F:$F,'01_異動主檔'!$B:$B,122,'01_異動主檔'!$D:$D,B28,'01_異動主檔'!$E:$E,"移入") | F28: =-SUMIFS('01_異動主檔'!$F:$F,'01_異動主檔'!$B:$B,122,'01_異動主檔'!$D:$D,B28,'01_異動主檔'!$E:$E,"移出") | G28: =SUMIFS('01_異動主檔'!$F:$F,'01_異動主檔'!$B:$B,122,'01_異動主檔'!$D:$D,B28,'01_異動主檔'!$E:$E,"新增") | H28: =-SUMIFS('01_異動主檔'!$F:$F,'01_異動主檔'!$B:$B,122,'01_異動主檔'!$D:$D,B28,'01_異動主檔'!$E:$E,"減列") | I28: =-SUMIFS('01_異動主檔'!$F:$F,'01_異動主檔'!$B:$B,122,'01_異動主檔'!$D:$D,B28,'01_異動主檔'!$E:$E,"精簡") | J28: =D28+E28+F28+G28+H28+I28
A29: A001 | B29: 人事處 | C29: 123 | D29: =J28 | E29: =SUMIFS('01_異動主檔'!$F:$F,'01_異動主檔'!$B:$B,123,'01_異動主檔'!$D:$D,B29,'01_異動主檔'!$E:$E,"移入") | F29: =-SUMIFS('01_異動主檔'!$F:$F,'01_異動主檔'!$B:$B,123,'01_異動主檔'!$D:$D,B29,'01_異動主檔'!$E:$E,"移出") | G29: =SUMIFS('01_異動主檔'!$F:$F,'01_異動主檔'!$B:$B,123,'01_異動主檔'!$D:$D,B29,'01_異動主檔'!$E:$E,"新增") | H29: =-SUMIFS('01_異動主檔'!$F:$F,'01_異動主檔'!$B:$B,123,'01_異動主檔'!$D:$D,B29,'01_異動主檔'!$E:$E,"減列") | I29: =-SUMIFS('01_異動主檔'!$F:$F,'01_異動主檔'!$B:$B,123,'01_異動主檔'!$D:$D,B29,'01_異動主檔'!$E:$E,"精簡") | J29: =D29+E29+F29+G29+H29+I29
A30: A001 | B30: 人事處 | C30: 124 | D30: =J29 | E30: =SUMIFS('01_異動主檔'!$F:$F,'01_異動主檔'!$B:$B,124,'01_異動主檔'!$D:$D,B30,'01_異動主檔'!$E:$E,"移入") | F30: =-SUMIFS('01_異動主檔'!$F:$F,'01_異動主檔'!$B:$B,124,'01_異動主檔'!$D:$D,B30,'01_異動主檔'!$E:$E,"移出") | G30: =SUMIFS('01_異動主檔'!$F:$F,'01_異動主檔'!$B:$B,124,'01_異動主檔'!$D:$D,B30,'01_異動主檔'!$E:$E,"新增") | H30: =-SUMIFS('01_異動主檔'!$F:$F,'01_異動主檔'!$B:$B,124,'01_異動主檔'!$D:$D,B30,'01_異動主檔'!$E:$E,"減列") | I30: =-SUMIFS('01_異動主檔'!$F:$F,'01_異動主檔'!$B:$B,124,'01_異動主檔'!$D:$D,B30,'01_異動主檔'!$E:$E,"精簡") | J30: =D30+E30+F30+G30+H30+I30
A31: A001 | B31: 人事處 | C31: 125 | D31: =J30 | E31: =SUMIFS('01_異動主檔'!$F:$F,'01_異動主檔'!$B:$B,125,'01_異動主檔'!$D:$D,B31,'01_異動主檔'!$E:$E,"移入") | F31: =-SUMIFS('01_異動主檔'!$F:$F,'01_異動主檔'!$B:$B,125,'01_異動主檔'!$D:$D,B31,'01_異動主檔'!$E:$E,"移出") | G31: =SUMIFS('01_異動主檔'!$F:$F,'01_異動主檔'!$B:$B,125,'01_異動主檔'!$D:$D,B31,'01_異動主檔'!$E:$E,"新增") | H31: =-SUMIFS('01_異動主檔'!$F:$F,'01_異動主檔'!$B:$B,125,'01_異動主檔'!$D:$D,B31,'01_異動主檔'!$E:$E,"減列") | I31: =-SUMIFS('01_異動主檔'!$F:$F,'01_異動主檔'!$B:$B,125,'01_異動主檔'!$D:$D,B31,'01_異動主檔'!$E:$E,"精簡") | J31: =D31+E31+F31+G31+H31+I31
A32: A002 | B32: 會計處 | C32: 99 | D32: ='02_年初員額設定'!C6 | E32: =SUMIFS('01_異動主檔'!$F:$F,'01_異動主檔'!$B:$B,99,'01_異動主檔'!$D:$D,B32,'01_異動主檔'!$E:$E,"移入") | F32: =-SUMIFS('01_異動主檔'!$F:$F,'01_異動主檔'!$B:$B,99,'01_異動主檔'!$D:$D,B32,'01_異動主檔'!$E:$E,"移出") | G32: =SUMIFS('01_異動主檔'!$F:$F,'01_異動主檔'!$B:$B,99,'01_異動主檔'!$D:$D,B32,'01_異動主檔'!$E:$E,"新增") | H32: =-SUMIFS('01_異動主檔'!$F:$F,'01_異動主檔'!$B:$B,99,'01_異動主檔'!$D:$D,B32,'01_異動主檔'!$E:$E,"減列") | I32: =-SUMIFS('01_異動主檔'!$F:$F,'01_異動主檔'!$B:$B,99,'01_異動主檔'!$D:$D,B32,'01_異動主檔'!$E:$E,"精簡") | J32: =D32+E32+F32+G32+H32+I32
A33: A002 | B33: 會計處 | C33: 100 | D33: =J32 | E33: =SUMIFS('01_異動主檔'!$F:$F,'01_異動主檔'!$B:$B,100,'01_異動主檔'!$D:$D,B33,'01_異動主檔'!$E:$E,"移入") | F33: =-SUMIFS('01_異動主檔'!$F:$F,'01_異動主檔'!$B:$B,100,'01_異動主檔'!$D:$D,B33,'01_異動主檔'!$E:$E,"移出") | G33: =SUMIFS('01_異動主檔'!$F:$F,'01_異動主檔'!$B:$B,100,'01_異動主檔'!$D:$D,B33,'01_異動主檔'!$E:$E,"新增") | H33: =-SUMIFS('01_異動主檔'!$F:$F,'01_異動主檔'!$B:$B,100,'01_異動主檔'!$D:$D,B33,'01_異動主檔'!$E:$E,"減列") | I33: =-SUMIFS('01_異動主檔'!$F:$F,'01_異動主檔'!$B:$B,100,'01_異動主檔'!$D:$D,B33,'01_異動主檔'!$E:$E,"精簡") | J33: =D33+E33+F33+G33+H33+I33
A34: A002 | B34: 會計處 | C34: 101 | D34: =J33 | E34: =SUMIFS('01_異動主檔'!$F:$F,'01_異動主檔'!$B:$B,101,'01_異動主檔'!$D:$D,B34,'01_異動主檔'!$E:$E,"移入") | F34: =-SUMIFS('01_異動主檔'!$F:$F,'01_異動主檔'!$B:$B,101,'01_異動主檔'!$D:$D,B34,'01_異動主檔'!$E:$E,"移出") | G34: =SUMIFS('01_異動主檔'!$F:$F,'01_異動主檔'!$B:$B,101,'01_異動主檔'!$D:$D,B34,'01_異動主檔'!$E:$E,"新增") | H34: =-SUMIFS('01_異動主檔'!$F:$F,'01_異動主檔'!$B:$B,101,'01_異動主檔'!$D:$D,B34,'01_異動主檔'!$E:$E,"減列") | I34: =-SUMIFS('01_異動主檔'!$F:$F,'01_異動主檔'!$B:$B,101,'01_異動主檔'!$D:$D,B34,'01_異動主檔'!$E:$E,"精簡") | J34: =D34+E34+F34+G34+H34+I34
A35: A002 | B35: 會計處 | C35: 102 | D35: =J34 | E35: =SUMIFS('01_異動主檔'!$F:$F,'01_異動主檔'!$B:$B,102,'01_異動主檔'!$D:$D,B35,'01_異動主檔'!$E:$E,"移入") | F35: =-SUMIFS('01_異動主檔'!$F:$F,'01_異動主檔'!$B:$B,102,'01_異動主檔'!$D:$D,B35,'01_異動主檔'!$E:$E,"移出") | G35: =SUMIFS('01_異動主檔'!$F:$F,'01_異動主檔'!$B:$B,102,'01_異動主檔'!$D:$D,B35,'01_異動主檔'!$E:$E,"新增") | H35: =-SUMIFS('01_異動主檔'!$F:$F,'01_異動主檔'!$B:$B,102,'01_異動主檔'!$D:$D,B35,'01_異動主檔'!$E:$E,"減列") | I35: =-SUMIFS('01_異動主檔'!$F:$F,'01_異動主檔'!$B:$B,102,'01_異動主檔'!$D:$D,B35,'01_異動主檔'!$E:$E,"精簡") | J35: =D35+E35+F35+G35+H35+I35
A36: A002 | B36: 會計處 | C36: 103 | D36: =J35 | E36: =SUMIFS('01_異動主檔'!$F:$F,'01_異動主檔'!$B:$B,103,'01_異動主檔'!$D:$D,B36,'01_異動主檔'!$E:$E,"移入") | F36: =-SUMIFS('01_異動主檔'!$F:$F,'01_異動主檔'!$B:$B,103,'01_異動主檔'!$D:$D,B36,'01_異動主檔'!$E:$E,"移出") | G36: =SUMIFS('01_異動主檔'!$F:$F,'01_異動主檔'!$B:$B,103,'01_異動主檔'!$D:$D,B36,'01_異動主檔'!$E:$E,"新增") | H36: =-SUMIFS('01_異動主檔'!$F:$F,'01_異動主檔'!$B:$B,103,'01_異動主檔'!$D:$D,B36,'01_異動主檔'!$E:$E,"減列") | I36: =-SUMIFS('01_異動主檔'!$F:$F,'01_異動主檔'!$B:$B,103,'01_異動主檔'!$D:$D,B36,'01_異動主檔'!$E:$E,"精簡") | J36: =D36+E36+F36+G36+H36+I36
A37: A002 | B37: 會計處 | C37: 104 | D37: =J36 | E37: =SUMIFS('01_異動主檔'!$F:$F,'01_異動主檔'!$B:$B,104,'01_異動主檔'!$D:$D,B37,'01_異動主檔'!$E:$E,"移入") | F37: =-SUMIFS('01_異動主檔'!$F:$F,'01_異動主檔'!$B:$B,104,'01_異動主檔'!$D:$D,B37,'01_異動主檔'!$E:$E,"移出") | G37: =SUMIFS('01_異動主檔'!$F:$F,'01_異動主檔'!$B:$B,104,'01_異動主檔'!$D:$D,B37,'01_異動主檔'!$E:$E,"新增") | H37: =-SUMIFS('01_異動主檔'!$F:$F,'01_異動主檔'!$B:$B,104,'01_異動主檔'!$D:$D,B37,'01_異動主檔'!$E:$E,"減列") | I37: =-SUMIFS('01_異動主檔'!$F:$F,'01_異動主檔'!$B:$B,104,'01_異動主檔'!$D:$D,B37,'01_異動主檔'!$E:$E,"精簡") | J37: =D37+E37+F37+G37+H37+I37
A38: A002 | B38: 會計處 | C38: 105 | D38: =J37 | E38: =SUMIFS('01_異動主檔'!$F:$F,'01_異動主檔'!$B:$B,105,'01_異動主檔'!$D:$D,B38,'01_異動主檔'!$E:$E,"移入") | F38: =-SUMIFS('01_異動主檔'!$F:$F,'01_異動主檔'!$B:$B,105,'01_異動主檔'!$D:$D,B38,'01_異動主檔'!$E:$E,"移出") | G38: =SUMIFS('01_異動主檔'!$F:$F,'01_異動主檔'!$B:$B,105,'01_異動主檔'!$D:$D,B38,'01_異動主檔'!$E:$E,"新增") | H38: =-SUMIFS('01_異動主檔'!$F:$F,'01_異動主檔'!$B:$B,105,'01_異動主檔'!$D:$D,B38,'01_異動主檔'!$E:$E,"減列") | I38: =-SUMIFS('01_異動主檔'!$F:$F,'01_異動主檔'!$B:$B,105,'01_異動主檔'!$D:$D,B38,'01_異動主檔'!$E:$E,"精簡") | J38: =D38+E38+F38+G38+H38+I38
A39: A002 | B39: 會計處 | C39: 106 | D39: =J38 | E39: =SUMIFS('01_異動主檔'!$F:$F,'01_異動主檔'!$B:$B,106,'01_異動主檔'!$D:$D,B39,'01_異動主檔'!$E:$E,"移入") | F39: =-SUMIFS('01_異動主檔'!$F:$F,'01_異動主檔'!$B:$B,106,'01_異動主檔'!$D:$D,B39,'01_異動主檔'!$E:$E,"移出") | G39: =SUMIFS('01_異動主檔'!$F:$F,'01_異動主檔'!$B:$B,106,'01_異動主檔'!$D:$D,B39,'01_異動主檔'!$E:$E,"新增") | H39: =-SUMIFS('01_異動主檔'!$F:$F,'01_異動主檔'!$B:$B,106,'01_異動主檔'!$D:$D,B39,'01_異動主檔'!$E:$E,"減列") | I39: =-SUMIFS('01_異動主檔'!$F:$F,'01_異動主檔'!$B:$B,106,'01_異動主檔'!$D:$D,B39,'01_異動主檔'!$E:$E,"精簡") | J39: =D39+E39+F39+G39+H39+I39
A40: A002 | B40: 會計處 | C40: 107 | D40: =J39 | E40: =SUMIFS('01_異動主檔'!$F:$F,'01_異動主檔'!$B:$B,107,'01_異動主檔'!$D:$D,B40,'01_異動主檔'!$E:$E,"移入") | F40: =-SUMIFS('01_異動主檔'!$F:$F,'01_異動主檔'!$B:$B,107,'01_異動主檔'!$D:$D,B40,'01_異動主檔'!$E:$E,"移出") | G40: =SUMIFS('01_異動主檔'!$F:$F,'01_異動主檔'!$B:$B,107,'01_異動主檔'!$D:$D,B40,'01_異動主檔'!$E:$E,"新增") | H40: =-SUMIFS('01_異動主檔'!$F:$F,'01_異動主檔'!$B:$B,107,'01_異動主檔'!$D:$D,B40,'01_異動主檔'!$E:$E,"減列") | I40: =-SUMIFS('01_異動主檔'!$F:$F,'01_異動主檔'!$B:$B,107,'01_異動主檔'!$D:$D,B40,'01_異動主檔'!$E:$E,"精簡") | J40: =D40+E40+F40+G40+H40+I40
A41: A002 | B41: 會計處 | C41: 108 | D41: =J40 | E41: =SUMIFS('01_異動主檔'!$F:$F,'01_異動主檔'!$B:$B,108,'01_異動主檔'!$D:$D,B41,'01_異動主檔'!$E:$E,"移入") | F41: =-SUMIFS('01_異動主檔'!$F:$F,'01_異動主檔'!$B:$B,108,'01_異動主檔'!$D:$D,B41,'01_異動主檔'!$E:$E,"移出") | G41: =SUMIFS('01_異動主檔'!$F:$F,'01_異動主檔'!$B:$B,108,'01_異動主檔'!$D:$D,B41,'01_異動主檔'!$E:$E,"新增") | H41: =-SUMIFS('01_異動主檔'!$F:$F,'01_異動主檔'!$B:$B,108,'01_異動主檔'!$D:$D,B41,'01_異動主檔'!$E:$E,"減列") | I41: =-SUMIFS('01_異動主檔'!$F:$F,'01_異動主檔'!$B:$B,108,'01_異動主檔'!$D:$D,B41,'01_異動主檔'!$E:$E,"精簡") | J41: =D41+E41+F41+G41+H41+I41
...

Sheet 04_異動明細
A1: 📋 異動明細（選擇機關名稱查看所有異動記錄）
A2: 查詢機關： | B2: （留空顯示全部） | D2: ← 請輸入機關名稱
A3: 流水號 | B3: 年度 | C3: 修正日期 | D3: 機關名稱 | E3: 調整類型 | F3: 人數 | G3: 事由 | H3: 備註
A5: 1 | B5: 99 | C5: 99/01 | D5: 人事處 | E5: 移入 | F5: 5 | G5: 業務調整
A6: 2 | B6: 99 | C6: 99/03 | D6: 人事處 | E6: 移出 | F6: 2 | G6: 屆齡退休
A7: 3 | B7: 99 | C7: 99/06 | D7: 第一組 | E7: 新增 | F7: 3 | G7: 編制調整 | H7: 新增一個科室
A8: 4 | B8: 99 | C8: 99/09 | D8: 台北分局 | E8: 移入 | F8: 4 | G8: 業務移撥
A9: 5 | B9: 100 | C9: 100/02 | D9: 人事處 | E9: 移入 | F9: 2 | G9: 考試分發
A10: 6 | B10: 100 | C10: 100/05 | D10: 會計處 | E10: 減列 | F10: 1 | G10: 組織精簡
A11: 7 | B11: 100 | C11: 100/08 | D11: 第二組 | E11: 移出 | F11: 3 | G11: 業務移撥 | H11: 調至其他單位
A12: 8 | B12: 101 | C12: 101/03 | D12: 人事處 | E12: 精簡 | F12: 2 | G12: 優退

Sheet 05_篾選器
A1: 🔍 篩選查詢（選擇條件快速篩選資料）
A3: 選擇年度： | B3: 全部 | C3: ← 留空或輸入民國年（如：99、114）
A4: 選擇機關： | B4: 全部 | D4: ← 留空顯示全部，或輸入機關名稱
A5: 調整類型： | B5: 全部 | D5: ← 留空或輸入：移入/移出/新增/減列/精簡
A6: ※ 建議使用 Excel 篩選功能（Ctrl+Shift+L）或樞紐分析表進行更彈性的查詢
A7: 流水號 | B7: 年度 | C7: 修正日期 | D7: 機關名稱 | E7: 調整類型 | F7: 人數 | G7: 事由 | H7: 備註
A8: 1 | B8: 99 | C8: 99/01 | D8: 人事處 | E8: 移入 | F8: 5 | G8: 業務調整
A9: 2 | B9: 99 | C9: 99/03 | D9: 人事處 | E9: 移出 | F9: 2 | G9: 屆齡退休
A10: 3 | B10: 99 | C10: 99/06 | D10: 第一組 | E10: 新增 | F10: 3 | G10: 編制調整 | H10: 新增一個科室
A11: 4 | B11: 99 | C11: 99/09 | D11: 台北分局 | E11: 移入 | F11: 4 | G11: 業務移撥
A12: 5 | B12: 100 | C12: 100/02 | D12: 人事處 | E12: 移入 | F12: 2 | G12: 考試分發
A13: 6 | B13: 100 | C13: 100/05 | D13: 會計處 | E13: 減列 | F13: 1 | G13: 組織精簡
A14: 7 | B14: 100 | C14: 100/08 | D14: 第二組 | E14: 移出 | F14: 3 | G14: 業務移撥 | H14: 調至其他單位
A15: 8 | B15: 101 | C15: 101/03 | D15: 人事處 | E15: 精簡 | F15: 2 | G15: 優退

Sheet 06_使用手冊
A1: 📖 人事員額管理系統 使用手冊
A3: 【一、系統架構】
A4: 本系統包含以下工作表：
A5: • 00_機關清冊：60個機關的基本資料（代碼+名稱）
A6: • 01_異動主檔：新增所有異動記錄（主要輸入區）
A7: • 02_年初員額設定：99年度請手動輸入，100年度起自動連動
A8: • 03_年度彙總：自動計算各機關各年度的員額變化
A9: • 04_異動明細：查詢特定機關的所有異動歷史
A10: • 05_篾選器：快速篩選特定條件的資料
A11: • 06_使用手冊：本說明文件
A13: 【二、如何新增資料】
A14: 1. 切換到「01_異動主檔」工作表
... A49: • 系統已擴充至125年度，足夠使用到民國125年（2036年）
