Workbook

Sheet 00_機關清冊
A1: 📌 機關清冊（系統唯一定義，請勿刪除）
A2: 機關代碼 | B2: 機關名稱 | C2: 備註
A3: A001 | B3: 人事處
A4: A002 | B4: 會計處
A5: A003 | B5: 政風處
A6: A004 | B6: 總務處
A7: A005 | B7: 資訊處
A8: A006 | B8: 法制處
A9: A007 | B9: 秘書處
A10: A008 | B10: 公關室
A11: B001 | B11: 第一組
A12: B002 | B12: 第二組
A13: B003 | B13: 第三組
A14: B004 | B14: 第四組
... A58: G008 | B58: 城區辦公室

Sheet 01_異動主檔
A1: 📝 異動主檔（請在此新增資料）
A2: 流水號 | B2: 年度 | C2: 修正日期 | D2: 機關名稱 | E2: 調整類型 | F2: 人數 | G2: 事由 | H2: 備註
A3: 💡 提示：「機關名稱」和「調整類型」請從下拉選單選擇｜「年度」請輸入或選擇民國年
A4: 1 | B4: 99 | C4: 99/01 | D4: 人事處 | E4: 移入 | F4: 5 | G4: 業務調整
A5: 2 | B5: 99 | C5: 99/03 | D5: 人事處 | E5: 移出 | F5: 2 | G5: 屆齡退休
A6: 3 | B6: 99 | C6: 99/06 | D6: 第一組 | E6: 新增 | F6: 3 | G6: 編制調整 | H6: 新增一個科室
A7: 4 | B7: 99 | C7: 99/09 | D7: 台北分局 | E7: 移入 | F7: 4 | G7: 業務移撥
A8: 5 | B8: 100 | C8: 100/02 | D8: 人事處 | E8: 移入 | F8: 2 | G8: 考試分發
A9: 6 | B9: 100 | C9: 100/05 | D9: 會計處 | E9: 減列 | F9: 1 | G9: 組織精簡
A10: 7 | B10: 100 | C10: 100/08 | D10: 第二組 | E10: 移出 | F10: 3 | G10: 業務移撥 | H10: 調至其他單位
A11: 8 | B11: 101 | C11: 101/03 | D11: 人事處 | E11: 精簡 | F11: 2 | G11: 優退
A12: 9 | B12: 101 | C12: 101/07 | D12: 新北分局 | E12: 新增 | F12: 5 | G12: 新設置 | H12: 新增分局
A13: 10 | B13: 102 | C13: 102/01 | D13: 政風處 | E13: 移入 | F13: 3 | G13: 業務調整
A14: 11 | B14: 103 | C14: 103/04 | D14: 第一組 | E14: 移出 | F14: 1 | G14: 屆齡退休
A15: 12 | B15: 104 | C15: 104/06 | D15: 人事處 | E15: 新增 | F15: 4 | G15: 編制調整 | H15: 業務擴張
A16: 13 | B16: 105 | C16: 105/02 | D16: 台北分局 | E16: 減列 | F16: 2 | G16: 組織整併

Sheet 03_年度彙總
A1: 📈 年度彙總（自動計算，請勿直接修改）
A2: ※ 自動彙總「01_異動主檔」的資料｜本表為唯讀，資料有誤請回「01_異動主檔」修改
A4: 機關名稱 | B4: 年度 | C4: 年初 | D4: 移入 | E4: 移出 | F4: 新增 | G4: 減列 | H4: 精簡 | I4: 年底
A5: 人事處 | B5: 99 | C5: ='02_年初員額設定'!B5 | D5: =SUMIFS('01_異動主檔'!$F:$F,'01_異動主檔'!$B:$B,99,'01_異動主檔'!$D:$D,A5,'01_異動主檔'!$E:$E,"移入") | E5: =-SUMIFS('01_異動主檔'!$F:$F,'01_異動主檔'!$B:$B,99,'01_異動主檔'!$D:$D,A5,'01_異動主檔'!$E:$E,"移出") | F5: =SUMIFS('01_異動主檔'!$F:$F,'01_異動主檔'!$B:$B,99,'01_異動主檔'!$D:$D,A5,'01_異動主檔'!$E:$E,"新增") | G5: =-SUMIFS('01_異動主檔'!$F:$F,'01_異動主檔'!$B:$B,99,'01_異動主檔'!$D:$D,A5,'01_異動主檔'!$E:$E,"減列") | H5: =-SUMIFS('01_異動主檔'!$F:$F,'01_異動主檔'!$B:$B,99,'01_異動主檔'!$D:$D,A5,'01_異動主檔'!$E:$E,"精簡") | I5: =C5+D5+E5+F5+G5+H5
A6: 人事處 | B6: 100 | C6: =I5 | D6: =SUMIFS('01_異動主檔'!$F:$F,'01_異動主檔'!$B:$B,100,'01_異動主檔'!$D:$D,A6,'01_異動主檔'!$E:$E,"移入") | E6: =-SUMIFS('01_異動主檔'!$F:$F,'01_異動主檔'!$B:$B,100,'01_異動主檔'!$D:$D,A6,'01_異動主檔'!$E:$E,"移出") | F6: =SUMIFS('01_異動主檔'!$F:$F,'01_異動主檔'!$B:$B,100,'01_異動主檔'!$D:$D,A6,'01_異動主檔'!$E:$E,"新增") | G6: =-SUMIFS('01_異動主檔'!$F:$F,'01_異動主檔'!$B:$B,100,'01_異動主檔'!$D:$D,A6,'01_異動主檔'!$E:$E,"減列") | H6: =-SUMIFS('01_異動主檔'!$F:$F,'01_異動主檔'!$B:$B,100,'01_異動主檔'!$D:$D,A6,'01_異動主檔'!$E:$E,"精簡") | I6: =C6+D6+E6+F6+G6+H6
A7: 人事處 | B7: 101 | C7: =I6 | D7: =SUMIFS('01_異動主檔'!$F:$F,'01_異動主檔'!$B:$B,101,'01_異動主檔'!$D:$D,A7,'01_異動主檔'!$E:$E,"移入") | E7: =-SUMIFS('01_異動主檔'!$F:$F,'01_異動主檔'!$B:$B,101,'01_異動主檔'!$D:$D,A7,'01_異動主檔'!$E:$E,"移出") | F7: =SUMIFS('01_異動主檔'!$F:$F,'01_異動主檔'!$B:$B,101,'01_異動主檔'!$D:$D,A7,'01_異動主檔'!$E:$E,"新增") | G7: =-SUMIFS('01_異動主檔'!$F:$F,'01_異動主檔'!$B:$B,101,'01_異動主檔'!$D:$D,A7,'01_異動主檔'!$E:$E,"減列") | H7: =-SUMIFS('01_異動主檔'!$F:$F,'01_異動主檔'!$B:$B,101,'01_異動主檔'!$D:$D,A7,'01_異動主檔'!$E:$E,"精簡") | I7: =C7+D7+E7+F7+G7+H7
A8: 人事處 | B8: 102 | C8: =I7 | D8: =SUMIFS('01_異動主檔'!$F:$F,'01_異動主檔'!$B:$B,102,'01_異動主檔'!$D:$D,A8,'01_異動主檔'!$E:$E,"移入") | E8: =-SUMIFS('01_異動主檔'!$F:$F,'01_異動主檔'!$B:$B,102,'01_異動主檔'!$D:$D,A8,'01_異動主檔'!$E:$E,"移出") | F8: =SUMIFS('01_異動主檔'!$F:$F,'01_異動主檔'!$B:$B,102,'01_異動主檔'!$D:$D,A8,'01_異動主檔'!$E:$E,"新增") | G8: =-SUMIFS('01_異動主檔'!$F:$F,'01_異動主檔'!$B:$B,102,'01_異動主檔'!$D:$D,A8,'01_異動主檔'!$E:$E,"減列") | H8: =-SUMIFS('01_異動主檔'!$F:$F,'01_異動主檔'!$B:$B,102,'01_異動主檔'!$D:$D,A8,'01_異動主檔'!$E:$E,"精簡") | I8: =C8+D8+E8+F8+G8+H8
A9: 人事處 | B9: 103 | C9: =I8 | D9: =SUMIFS('01_異動主檔'!$F:$F,'01_異動主檔'!$B:$B,103,'01_異動主檔'!$D:$D,A9,'01_異動主檔'!$E:$E,"移入") | E9: =-SUMIFS('01_異動主檔'!$F:$F,'01_異動主檔'!$B:$B,103,'01_異動主檔'!$D:$D,A9,'01_異動主檔'!$E:$E,"移出") | F9: =SUMIFS('01_異動主檔'!$F:$F,'01_異動主檔'!$B:$B,103,'01_異動主檔'!$D:$D,A9,'01_異動主檔'!$E:$E,"新增") | G9: =-SUMIFS('01_異動主檔'!$F:$F,'01_異動主檔'!$B:$B,103,'01_異動主檔'!$D:$D,A9,'01_異動主檔'!$E:$E,"減列") | H9: =-SUMIFS('01_異動主檔'!$F:$F,'01_異動主檔'!$B:$B,103,'01_異動主檔'!$D:$D,A9,'01_異動主檔'!$E:$E,"精簡") | I9: =C9+D9+E9+F9+G9+H9
A10: 人事處 | B10: 104 | C10: =I9 | D10: =SUMIFS('01_異動主檔'!$F:$F,'01_異動主檔'!$B:$B,104,'01_異動主檔'!$D:$D,A10,'01_異動主檔'!$E:$E,"移入") | E10: =-SUMIFS('01_異動主檔'!$F:$F,'01_異動主檔'!$B:$B,104,'01_異動主檔'!$D:$D,A10,'01_異動主檔'!$E:$E,"移出") | F10: =SUMIFS('01_異動主檔'!$F:$F,'01_異動主檔'!$B:$B,104,'01_異動主檔'!$D:$D,A10,'01_異動主檔'!$E:$E,"新增") | G10: =-SUMIFS('01_異動主檔'!$F:$F,'01_異動主檔'!$B:$B,104,'01_異動主檔'!$D:$D,A10,'01_異動主檔'!$E:$E,"減列") | H10: =-SUMIFS('01_異動主檔'!$F:$F,'01_異動主檔'!$B:$B,104,'01_異動主檔'!$D:$D,A10,'01_異動主檔'!$E:$E,"精簡") | I10: =C10+D10+E10+F10+G10+H10
A11: 人事處 | B11: 105 | C11: =I10 | D11: =SUMIFS('01_異動主檔'!$F:$F,'01_異動主檔'!$B:$B,105,'01_異動主檔'!$D:$D,A11,'01_異動主檔'!$E:$E,"移入") | E11: =-SUMIFS('01_異動主檔'!$F:$F,'01_異動主檔'!$B:$B,105,'01_異動主檔'!$D:$D,A11,'01_異動主檔'!$E:$E,"移出") | F11: =SUMIFS('01_異動主檔'!$F:$F,'01_異動主檔'!$B:$B,105,'01_異動主檔'!$D:$D,A11,'01_異動主檔'!$E:$E,"新增") | G11: =-SUMIFS('01_異動主檔'!$F:$F,'01_異動主檔'!$B:$B,105,'01_異動主檔'!$D:$D,A11,'01_異動主檔'!$E:$E,"減列") | H11: =-SUMIFS('01_異動主檔'!$F:$F,'01_異動主檔'!$B:$B,105,'01_異動主檔'!$D:$D,A11,'01_異動主檔'!$E:$E,"精簡") | I11: =C11+D11+E11+F11+G11+H11
A12: 人事處 | B12: 106 | C12: =I11 | D12: =SUMIFS('01_異動主檔'!$F:$F,'01_異動主檔'!$B:$B,106,'01_異動主檔'!$D:$D,A12,'01_異動主檔'!$E:$E,"移入") | E12: =-SUMIFS('01_異動主檔'!$F:$F,'01_異動主檔'!$B:$B,106,'01_異動主檔'!$D:$D,A12,'01_異動主檔'!$E:$E,"移出") | F12: =SUMIFS('01_異動主檔'!$F:$F,'01_異動主檔'!$B:$B,106,'01_異動主檔'!$D:$D,A12,'01_異動主檔'!$E:$E,"新增") | G12: =-SUMIFS('01_異動主檔'!$F:$F,'01_異動主檔'!$B:$B,106,'01_異動主檔'!$D:$D,A12,'01_異動主檔'!$E:$E,"減列") | H12: =-SUMIFS('01_異動主檔'!$F:$F,'01_異動主檔'!$B:$B,106,'01_異動主檔'!$D:$D,A12,'01_異動主檔'!$E:$E,"精簡") | I12: =C12+D12+E12+F12+G12+H12
A13: 人事處 | B13: 107 | C13: =I12 | D13: =SUMIFS('01_異動主檔'!$F:$F,'01_異動主檔'!$B:$B,107,'01_異動主檔'!$D:$D,A13,'01_異動主檔'!$E:$E,"移入") | E13: =-SUMIFS('01_異動主檔'!$F:$F,'01_異動主檔'!$B:$B,107,'01_異動主檔'!$D:$D,A13,'01_異動主檔'!$E:$E,"移出") | F13: =SUMIFS('01_異動主檔'!$F:$F,'01_異動主檔'!$B:$B,107,'01_異動主檔'!$D:$D,A13,'01_異動主檔'!$E:$E,"新增") | G13: =-SUMIFS('01_異動主檔'!$F:$F,'01_異動主檔'!$B:$B,107,'01_異動主檔'!$D:$D,A13,'01_異動主檔'!$E:$E,"減列") | H13: =-SUMIFS('01_異動主檔'!$F:$F,'01_異動主檔'!$B:$B,107,'01_異動主檔'!$D:$D,A13,'01_異動主檔'!$E:$E,"精簡") | I13: =C13+D13+E13+F13+G13+H13
A14: 人事處 | B14: 108 | C14: =I13 | D14: =SUMIFS('01_異動主檔'!$F:$F,'01_異動主檔'!$B:$B,108,'01_異動主檔'!$D:$D,A14,'01_異動主檔'!$E:$E,"移入") | E14: =-SUMIFS('01_異動主檔'!$F:$F,'01_異動主檔'!$B:$B,108,'01_異動主檔'!$D:$D,A14,'01_異動主檔'!$E:$E,"移出") | F14: =SUMIFS('01_異動主檔'!$F:$F,'01_異動主檔'!$B:$B,108,'01_異動主檔'!$D:$D,A14,'01_異動主檔'!$E:$E,"新增") | G14: =-SUMIFS('01_異動主檔'!$F:$F,'01_異動主檔'!$B:$B,108,'01_異動主檔'!$D:$D,A14,'01_異動主檔'!$E:$E,"減列") | H14: =-SUMIFS('01_異動主檔'!$F:$F,'01_異動主檔'!$B:$B,108,'01_異動主檔'!$D:$D,A14,'01_異動主檔'!$E:$E,"精簡") | I14: =C14+D14+E14+F14+G14+H14
A15: 人事處 | B15: 109 | C15: =I14 | D15: =SUMIFS('01_異動主檔'!$F:$F,'01_異動主檔'!$B:$B,109,'01_異動主檔'!$D:$D,A15,'01_異動主檔'!$E:$E,"移入") | E15: =-SUMIFS('01_異動主檔'!$F:$F,'01_異動主檔'!$B:$B,109,'01_異動主檔'!$D:$D,A15,'01_異動主檔'!$E:$E,"移出") | F15: =SUMIFS('01_異動主檔'!$F:$F,'01_異動主檔'!$B:$B,109,'01_異動主檔'!$D:$D,A15,'01_異動主檔'!$E:$E,"新增") | G15: =-SUMIFS('01_異動主檔'!$F:$F,'01_異動主檔'!$B:$B,109,'01_異動主檔'!$D:$D,A15,'01_異動主檔'!$E:$E,"減列") | H15: =-SUMIFS('01_異動主檔'!$F:$F,'01_異動主檔'!$B:$B,109,'01_異動主檔'!$D:$D,A15,'01_異動主檔'!$E:$E,"精簡") | I15: =C15+D15+E15+F15+G15+H15
A16: 人事處 | B16: 110 | C16: =I15 | D16: =SUMIFS('01_異動主檔'!$F:$F,'01_異動主檔'!$B:$B,110,'01_異動主檔'!$D:$D,A16,'01_異動主檔'!$E:$E,"移入") | E16: =-SUMIFS('01_異動主檔'!$F:$F,'01_異動主檔'!$B:$B,110,'01_異動主檔'!$D:$D,A16,'01_異動主檔'!$E:$E,"移出") | F16: =SUMIFS('01_異動主檔'!$F:$F,'01_異動主檔'!$B:$B,110,'01_異動主檔'!$D:$D,A16,'01_異動主檔'!$E:$E,"新增") | G16: =-SUMIFS('01_異動主檔'!$F:$F,'01_異動主檔'!$B:$B,110,'01_異動主檔'!$D:$D,A16,'01_異動主檔'!$E:$E,"減列") | H16: =-SUMIFS('01_異動主檔'!$F:$F,'01_異動主檔'!$B:$B,110,'01_異動主檔'!$D:$D,A16,'01_異動主檔'!$E:$E,"精簡") | I16: =C16+D16+E16+F16+G16+H16
A17: 人事處 | B17: 111 | C17: =I16 | D17: =SUMIFS('01_異動主檔'!$F:$F,'01_異動主檔'!$B:$B,111,'01_異動主檔'!$D:$D,A17,'01_異動主檔'!$E:$E,"移入") | E17: =-SUMIFS('01_異動主檔'!$F:$F,'01_異動主檔'!$B:$B,111,'01_異動主檔'!$D:$D,A17,'01_異動主檔'!$E:$E,"移出") | F17: =SUMIFS('01_異動主檔'!$F:$F,'01_異動主檔'!$B:$B,111,'01_異動主檔'!$D:$D,A17,'01_異動主檔'!$E:$E,"新增") | G17: =-SUMIFS('01_異動主檔'!$F:$F,'01_異動主檔'!$B:$B,111,'01_異動主檔'!$D:$D,A17,'01_異動主檔'!$E:$E,"減列") | H17: =-SUMIFS('01_異動主檔'!$F:$F,'01_異動主檔'!$B:$B,111,'01_異動主檔'!$D:$D,A17,'01_異動主檔'!$E:$E,"精簡") | I17: =C17+D17+E17+F17+G17+H17
A18: 人事處 | B18: 112 | C18: =I17 | D18: =SUMIFS('01_異動主檔'!$F:$F,'01_異動主檔'!$B:$B,112,'01_異動主檔'!$D:$D,A18,'01_異動主檔'!$E:$E,"移入") | E18: =-SUMIFS('01_異動主檔'!$F:$F,'01_異動主檔'!$B:$B,112,'01_異動主檔'!$D:$D,A18,'01_異動主檔'!$E:$E,"移出") | F18: =SUMIFS('01_異動主檔'!$F:$F,'01_異動主檔'!$B:$B,112,'01_異動主檔'!$D:$D,A18,'01_異動主檔'!$E:$E,"新增") | G18: =-SUMIFS('01_異動主檔'!$F:$F,'01_異動主檔'!$B:$B,112,'01_異動主檔'!$D:$D,A18,'01_異動主檔'!$E:$E,"減列") | H18: =-SUMIFS('01_異動主檔'!$F:$F,'01_異動主檔'!$B:$B,112,'01_異動主檔'!$D:$D,A18,'01_異動主檔'!$E:$E,"精簡") | I18: =C18+D18+E18+F18+G18+H18
A19: 人事處 | B19: 113 | C19: =I18 | D19: =SUMIFS('01_異動主檔'!$F:$F,'01_異動主檔'!$B:$B,113,'01_異動主檔'!$D:$D,A19,'01_異動主檔'!$E:$E,"移入") | E19: =-SUMIFS('01_異動主檔'!$F:$F,'01_異動主檔'!$B:$B,113,'01_異動主檔'!$D:$D,A19,'01_異動主檔'!$E:$E,"移出") | F19: =SUMIFS('01_異動主檔'!$F:$F,'01_異動主檔'!$B:$B,113,'01_異動主檔'!$D:$D,A19,'01_異動主檔'!$E:$E,"新增") | G19: =-SUMIFS('01_異動主檔'!$F:$F,'01_異動主檔'!$B:$B,113,'01_異動主檔'!$D:$D,A19,'01_異動主檔'!$E:$E,"減列") | H19: =-SUMIFS('01_異動主檔'!$F:$F,'01_異動主檔'!$B:$B,113,'01_異動主檔'!$D:$D,A19,'01_異動主檔'!$E:$E,"精簡") | I19: =C19+D19+E19+F19+G19+H19
A20: 人事處 | B20: 114 | C20: =I19 | D20: =SUMIFS('01_異動主檔'!$F:$F,'01_異動主檔'!$B:$B,114,'01_異動主檔'!$D:$D,A20,'01_異動主檔'!$E:$E,"移入") | E20: =-SUMIFS('01_異動主檔'!$F:$F,'01_異動主檔'!$B:$B,114,'01_異動主檔'!$D:$D,A20,'01_異動主檔'!$E:$E,"移出") | F20: =SUMIFS('01_異動主檔'!$F:$F,'01_異動主檔'!$B:$B,114,'01_異動主檔'!$D:$D,A20,'01_異動主檔'!$E:$E,"新增") | G20: =-SUMIFS('01_異動主檔'!$F:$F,'01_異動主檔'!$B:$B,114,'01_異動主檔'!$D:$D,A20,'01_異動主檔'!$E:$E,"減列") | H20: =-SUMIFS('01_異動主檔'!$F:$F,'01_異動主檔'!$B:$B,114,'01_異動主檔'!$D:$D,A20,'01_異動主檔'!$E:$E,"精簡") | I20: =C20+D20+E20+F20+G20+H20
A21: 人事處 | B21: 115 | C21: =I20 | D21: =SUMIFS('01_異動主檔'!$F:$F,'01_異動主檔'!$B:$B,115,'01_異動主檔'!$D:$D,A21,'01_異動主檔'!$E:$E,"移入") | E21: =-SUMIFS('01_異動主檔'!$F:$F,'01_異動主檔'!$B:$B,115,'01_異動主檔'!$D:$D,A21,'01_異動主檔'!$E:$E,"移出") | F21: =SUMIFS('01_異動主檔'!$F:$F,'01_異動主檔'!$B:$B,115,'01_異動主檔'!$D:$D,A21,'01_異動主檔'!$E:$E,"新增") | G21: =-SUMIFS('01_異動主檔'!$F:$F,'01_異動主檔'!$B:$B,115,'01_異動主檔'!$D:$D,A21,'01_異動主檔'!$E:$E,"減列") | H21: =-SUMIFS('01_異動主檔'!$F:$F,'01_異動主檔'!$B:$B,115,'01_異動主檔'!$D:$D,A21,'01_異動主檔'!$E:$E,"精簡") | I21: =C21+D21+E21+F21+G21+H21
A22: 人事處 | B22: 116 | C22: =I21 | D22: =SUMIFS('01_異動主檔'!$F:$F,'01_異動主檔'!$B:$B,116,'01_異動主檔'!$D:$D,A22,'01_異動主檔'!$E:$E,"移入") | E22: =-SUMIFS('01_異動主檔'!$F:$F,'01_異動主檔'!$B:$B,116,'01_異動主檔'!$D:$D,A22,'01_異動主檔'!$E:$E,"移出") | F22: =SUMIFS('01_異動主檔'!$F:$F,'01_異動主檔'!$B:$B,116,'01_異動主檔'!$D:$D,A22,'01_異動主檔'!$E:$E,"新增") | G22: =-SUMIFS('01_異動主檔'!$F:$F,'01_異動主檔'!$B:$B,116,'01_異動主檔'!$D:$D,A22,'01_異動主檔'!$E:$E,"減列") | H22: =-SUMIFS('01_異動主檔'!$F:$F,'01_異動主檔'!$B:$B,116,'01_異動主檔'!$D:$D,A22,'01_異動主檔'!$E:$E,"精簡") | I22: =C22+D22+E22+F22+G22+H22
A23: 人事處 | B23: 117 | C23: =I22 | D23: =SUMIFS('01_異動主檔'!$F:$F,'01_異動主檔'!$B:$B,117,'01_異動主檔'!$D:$D,A23,'01_異動主檔'!$E:$E,"移入") | E23: =-SUMIFS('01_異動主檔'!$F:$F,'01_異動主檔'!$B:$B,117,'01_異動主檔'!$D:$D,A23,'01_異動主檔'!$E:$E,"移出") | F23: =SUMIFS('01_異動主檔'!$F:$F,'01_異動主檔'!$B:$B,117,'01_異動主檔'!$D:$D,A23,'01_異動主檔'!$E:$E,"新增") | G23: =-SUMIFS('01_異動主檔'!$F:$F,'01_異動主檔'!$B:$B,117,'01_異動主檔'!$D:$D,A23,'01_異動主檔'!$E:$E,"減列") | H23: =-SUMIFS('01_異動主檔'!$F:$F,'01_異動主檔'!$B:$B,117,'01_異動主檔'!$D:$D,A23,'01_異動主檔'!$E:$E,"精簡") | I23: =C23+D23+E23+F23+G23+H23
A24: 人事處 | B24: 118 | C24: =I23 | D24: =SUMIFS('01_異動主檔'!$F:$F,'01_異動主檔'!$B:$B,118,'01_異動主檔'!$D:$D,A24,'01_異動主檔'!$E:$E,"移入") | E24: =-SUMIFS('01_異動主檔'!$F:$F,'01_異動主檔'!$B:$B,118,'01_異動主檔'!$D:$D,A24,'01_異動主檔'!$E:$E,"移出") | F24: =SUMIFS('01_異動主檔'!$F:$F,'01_異動主檔'!$B:$B,118,'01_異動主檔'!$D:$D,A24,'01_異動主檔'!$E:$E,"新增") | G24: =-SUMIFS('01_異動主檔'!$F:$F,'01_異動主檔'!$B:$B,118,'01_異動主檔'!$D:$D,A24,'01_異動主檔'!$E:$E,"減列") | H24: =-SUMIFS('01_異動主檔'!$F:$F,'01_異動主檔'!$B:$B,118,'01_異動主檔'!$D:$D,A24,'01_異動主檔'!$E:$E,"精簡") | I24: =C24+D24+E24+F24+G24+H24
A25: 人事處 | B25: 119 | C25: =I24 | D25: =SUMIFS('01_異動主檔'!$F:$F,'01_異動主檔'!$B:$B,119,'01_異動主檔'!$D:$D,A25,'01_異動主檔'!$E:$E,"移入") | E25: =-SUMIFS('01_異動主檔'!$F:$F,'01_異動主檔'!$B:$B,119,'01_異動主檔'!$D:$D,A25,'01_異動主檔'!$E:$E,"移出") | F25: =SUMIFS('01_異動主檔'!$F:$F,'01_異動主檔'!$B:$B,119,'01_異動主檔'!$D:$D,A25,'01_異動主檔'!$E:$E,"新增") | G25: =-SUMIFS('01_異動主檔'!$F:$F,'01_異動主檔'!$B:$B,119,'01_異動主檔'!$D:$D,A25,'01_異動主檔'!$E:$E,"減列") | H25: =-SUMIFS('01_異動主檔'!$F:$F,'01_異動主檔'!$B:$B,119,'01_異動主檔'!$D:$D,A25,'01_異動主檔'!$E:$E,"精簡") | I25: =C25+D25+E25+F25+G25+H25
A26: 人事處 | B26: 120 | C26: =I25 | D26: =SUMIFS('01_異動主檔'!$F:$F,'01_異動主檔'!$B:$B,120,'01_異動主檔'!$D:$D,A26,'01_異動主檔'!$E:$E,"移入") | E26: =-SUMIFS('01_異動主檔'!$F:$F,'01_異動主檔'!$B:$B,120,'01_異動主檔'!$D:$D,A26,'01_異動主檔'!$E:$E,"移出") | F26: =SUMIFS('01_異動主檔'!$F:$F,'01_異動主檔'!$B:$B,120,'01_異動主檔'!$D:$D,A26,'01_異動主檔'!$E:$E,"新增") | G26: =-SUMIFS('01_異動主檔'!$F:$F,'01_異動主檔'!$B:$B,120,'01_異動主檔'!$D:$D,A26,'01_異動主檔'!$E:$E,"減列") | H26: =-SUMIFS('01_異動主檔'!$F:$F,'01_異動主檔'!$B:$B,120,'01_異動主檔'!$D:$D,A26,'01_異動主檔'!$E:$E,"精簡") | I26: =C26+D26+E26+F26+G26+H26
A27: 人事處 | B27: 121 | C27: =I26 | D27: =SUMIFS('01_異動主檔'!$F:$F,'01_異動主檔'!$B:$B,121,'01_異動主檔'!$D:$D,A27,'01_異動主檔'!$E:$E,"移入") | E27: =-SUMIFS('01_異動主檔'!$F:$F,'01_異動主檔'!$B:$B,121,'01_異動主檔'!$D:$D,A27,'01_異動主檔'!$E:$E,"移出") | F27: =SUMIFS('01_異動主檔'!$F:$F,'01_異動主檔'!$B:$B,121,'01_異動主檔'!$D:$D,A27,'01_異動主檔'!$E:$E,"新增") | G27: =-SUMIFS('01_異動主檔'!$F:$F,'01_異動主檔'!$B:$B,121,'01_異動主檔'!$D:$D,A27,'01_異動主檔'!$E:$E,"減列") | H27: =-SUMIFS('01_異動主檔'!$F:$F,'01_異動主檔'!$B:$B,121,'01_異動主檔'!$D:$D,A27,'01_異動主檔'!$E:$E,"精簡") | I27: =C27+D27+E27+F27+G27+H27
A28: 人事處 | B28: 122 | C28: =I27 | D28: =SUMIFS('01_異動主檔'!$F:$F,'01_異動主檔'!$B:$B,122,'01_異動主檔'!$D:$D,A28,'01_異動主檔'!$E:$E,"移入") | E28: =-SUMIFS('01_異動主檔'!$F:$F,'01_異動主檔'!$B:$B,122,'01_異動主檔'!$D:$D,A28,'01_異動主檔'!$E:$E,"移出") | F28: =SUMIFS('01_異動主檔'!$F:$F,'01_異動主檔'!$B:$B,122,'01_異動主檔'!$D:$D,A28,'01_異動主檔'!$E:$E,"新增") | G28: =-SUMIFS('01_異動主檔'!$F:$F,'01_異動主檔'!$B:$B,122,'01_異動主檔'!$D:$D,A28,'01_異動主檔'!$E:$E,"減列") | H28: =-SUMIFS('01_異動主檔'!$F:$F,'01_異動主檔'!$B:$B,122,'01_異動主檔'!$D:$D,A28,'01_異動主檔'!$E:$E,"精簡") | I28: =C28+D28+E28+F28+G28+H28
A29: 人事處 | B29: 123 | C29: =I28 | D29: =SUMIFS('01_異動主檔'!$F:$F,'01_異動主檔'!$B:$B,123,'01_異動主檔'!$D:$D,A29,'01_異動主檔'!$E:$E,"移入") | E29: =-SUMIFS('01_異動主檔'!$F:$F,'01_異動主檔'!$B:$B,123,'01_異動主檔'!$D:$D,A29,'01_異動主檔'!$E:$E,"移出") | F29: =SUMIFS('01_異動主檔'!$F:$F,'01_異動主檔'!$B:$B,123,'01_異動主檔'!$D:$D,A29,'01_異動主檔'!$E:$E,"新增") | G29: =-SUMIFS('01_異動主檔'!$F:$F,'01_異動主檔'!$B:$B,123,'01_異動主檔'!$D:$D,A29,'01_異動主檔'!$E:$E,"減列") | H29: =-SUMIFS('01_異動主檔'!$F:$F,'01_異動主檔'!$B:$B,123,'01_異動主檔'!$D:$D,A29,'01_異動主檔'!$E:$E,"精簡") | I29: =C29+D29+E29+F29+G29+H29
A30: 人事處 | B30: 124 | C30: =I29 | D30: =SUMIFS('01_異動主檔'!$F:$F,'01_異動主檔'!$B:$B,124,'01_異動主檔'!$D:$D,A30,'01_異動主檔'!$E:$E,"移入") | E30: =-SUMIFS('01_異動主檔'!$F:$F,'01_異動主檔'!$B:$B,124,'01_異動主檔'!$D:$D,A30,'01_異動主檔'!$E:$E,"移出") | F30: =SUMIFS('01_異動主檔'!$F:$F,'01_異動主檔'!$B:$B,124,'01_異動主檔'!$D:$D,A30,'01_異動主檔'!$E:$E,"新增") | G30: =-SUMIFS('01_異動主檔'!$F:$F,'01_異動主檔'!$B:$B,124,'01_異動主檔'!$D:$D,A30,'01_異動主檔'!$E:$E,"減列") | H30: =-SUMIFS('01_異動主檔'!$F:$F,'01_異動主檔'!$B:$B,124,'01_異動主檔'!$D:$D,A30,'01_異動主檔'!$E:$E,"精簡") | I30: =C30+D30+E30+F30+G30+H30
A31: 人事處 | B31: 125 | C31: =I30 | D31: =SUMIFS('01_異動主檔'!$F:$F,'01_異動主檔'!$B:$B,125,'01_異動主檔'!$D:$D,A31,'01_異動主檔'!$E:$E,"移入") | E31: =-SUMIFS('01_異動主檔'!$F:$F,'01_異動主檔'!$B:$B,125,'01_異動主檔'!$D:$D,A31,'01_異動主檔'!$E:$E,"移出") | F31: =SUMIFS('01_異動主檔'!$F:$F,'01_異動主檔'!$B:$B,125,'01_異動主檔'!$D:$D,A31,'01_異動主檔'!$E:$E,"新增") | G31: =-SUMIFS('01_異動主檔'!$F:$F,'01_異動主檔'!$B:$B,125,'01_異動主檔'!$D:$D,A31,'01_異動主檔'!$E:$E,"減列") | H31: =-SUMIFS('01_異動主檔'!$F:$F,'01_異動主檔'!$B:$B,125,'01_異動主檔'!$D:$D,A31,'01_異動主檔'!$E:$E,"精簡") | I31: =C31+D31+E31+F31+G31+H31
A32: 會計處 | B32: 99 | C32: ='02_年初員額設定'!B6 | D32: =SUMIFS('01_異動主檔'!$F:$F,'01_異動主檔'!$B:$B,99,'01_異動主檔'!$D:$D,A32,'01_異動主檔'!$E:$E,"移入") | E32: =-SUMIFS('01_異動主檔'!$F:$F,'01_異動主檔'!$B:$B,99,'01_異動主檔'!$D:$D,A32,'01_異動主檔'!$E:$E,"移出") | F32: =SUMIFS('01_異動主檔'!$F:$F,'01_異動主檔'!$B:$B,99,'01_異動主檔'!$D:$D,A32,'01_異動主檔'!$E:$E,"新增") | G32: =-SUMIFS('01_異動主檔'!$F:$F,'01_異動主檔'!$B:$B,99,'01_異動主檔'!$D:$D,A32,'01_異動主檔'!$E:$E,"減列") | H32: =-SUMIFS('01_異動主檔'!$F:$F,'01_異動主檔'!$B:$B,99,'01_異動主檔'!$D:$D,A32,'01_異動主檔'!$E:$E,"精簡") | I32: =C32+D32+E32+F32+G32+H32
A33: 會計處 | B33: 100 | C33: =I32 | D33: =SUMIFS('01_異動主檔'!$F:$F,'01_異動主檔'!$B:$B,100,'01_異動主檔'!$D:$D,A33,'01_異動主檔'!$E:$E,"移入") | E33: =-SUMIFS('01_異動主檔'!$F:$F,'01_異動主檔'!$B:$B,100,'01_異動主檔'!$D:$D,A33,'01_異動主檔'!$E:$E,"移出") | F33: =SUMIFS('01_異動主檔'!$F:$F,'01_異動主檔'!$B:$B,100,'01_異動主檔'!$D:$D,A33,'01_異動主檔'!$E:$E,"新增") | G33: =-SUMIFS('01_異動主檔'!$F:$F,'01_異動主檔'!$B:$B,100,'01_異動主檔'!$D:$D,A33,'01_異動主檔'!$E:$E,"減列") | H33: =-SUMIFS('01_異動主檔'!$F:$F,'01_異動主檔'!$B:$B,100,'01_異動主檔'!$D:$D,A33,'01_異動主檔'!$E:$E,"精簡") | I33: =C33+D33+E33+F33+G33+H33
A34: 會計處 | B34: 101 | C34: =I33 | D34: =SUMIFS('01_異動主檔'!$F:$F,'01_異動主檔'!$B:$B,101,'01_異動主檔'!$D:$D,A34,'01_異動主檔'!$E:$E,"移入") | E34: =-SUMIFS('01_異動主檔'!$F:$F,'01_異動主檔'!$B:$B,101,'01_異動主檔'!$D:$D,A34,'01_異動主檔'!$E:$E,"移出") | F34: =SUMIFS('01_異動主檔'!$F:$F,'01_異動主檔'!$B:$B,101,'01_異動主檔'!$D:$D,A34,'01_異動主檔'!$E:$E,"新增") | G34: =-SUMIFS('01_異動主檔'!$F:$F,'01_異動主檔'!$B:$B,101,'01_異動主檔'!$D:$D,A34,'01_異動主檔'!$E:$E,"減列") | H34: =-SUMIFS('01_異動主檔'!$F:$F,'01_異動主檔'!$B:$B,101,'01_異動主檔'!$D:$D,A34,'01_異動主檔'!$E:$E,"精簡") | I34: =C34+D34+E34+F34+G34+H34
A35: 會計處 | B35: 102 | C35: =I34 | D35: =SUMIFS('01_異動主檔'!$F:$F,'01_異動主檔'!$B:$B,102,'01_異動主檔'!$D:$D,A35,'01_異動主檔'!$E:$E,"移入") | E35: =-SUMIFS('01_異動主檔'!$F:$F,'01_異動主檔'!$B:$B,102,'01_異動主檔'!$D:$D,A35,'01_異動主檔'!$E:$E,"移出") | F35: =SUMIFS('01_異動主檔'!$F:$F,'01_異動主檔'!$B:$B,102,'01_異動主檔'!$D:$D,A35,'01_異動主檔'!$E:$E,"新增") | G35: =-SUMIFS('01_異動主檔'!$F:$F,'01_異動主檔'!$B:$B,102,'01_異動主檔'!$D:$D,A35,'01_異動主檔'!$E:$E,"減列") | H35: =-SUMIFS('01_異動主檔'!$F:$F,'01_異動主檔'!$B:$B,102,'01_異動主檔'!$D:$D,A35,'01_異動主檔'!$E:$E,"精簡") | I35: =C35+D35+E35+F35+G35+H35
A36: 會計處 | B36: 103 | C36: =I35 | D36: =SUMIFS('01_異動主檔'!$F:$F,'01_異動主檔'!$B:$B,103,'01_異動主檔'!$D:$D,A36,'01_異動主檔'!$E:$E,"移入") | E36: =-SUMIFS('01_異動主檔'!$F:$F,'01_異動主檔'!$B:$B,103,'01_異動主檔'!$D:$D,A36,'01_異動主檔'!$E:$E,"移出") | F36: =SUMIFS('01_異動主檔'!$F:$F,'01_異動主檔'!$B:$B,103,'01_異動主檔'!$D:$D,A36,'01_異動主檔'!$E:$E,"新增") | G36: =-SUMIFS('01_異動主檔'!$F:$F,'01_異動主檔'!$B:$B,103,'01_異動主檔'!$D:$D,A36,'01_異動主檔'!$E:$E,"減列") | H36: =-SUMIFS('01_異動主檔'!$F:$F,'01_異動主檔'!$B:$B,103,'01_異動主檔'!$D:$D,A36,'01_異動主檔'!$E:$E,"精簡") | I36: =C36+D36+E36+F36+G36+H36
A37: 會計處 | B37: 104 | C37: =I36 | D37: =SUMIFS('01_異動主檔'!$F:$F,'01_異動主檔'!$B:$B,104,'01_異動主檔'!$D:$D,A37,'01_異動主檔'!$E:$E,"移入") | E37: =-SUMIFS('01_異動主檔'!$F:$F,'01_異動主檔'!$B:$B,104,'01_異動主檔'!$D:$D,A37,'01_異動主檔'!$E:$E,"移出") | F37: =SUMIFS('01_異動主檔'!$F:$F,'01_異動主檔'!$B:$B,104,'01_異動主檔'!$D:$D,A37,'01_異動主檔'!$E:$E,"新增") | G37: =-SUMIFS('01_異動主檔'!$F:$F,'01_異動主檔'!$B:$B,104,'01_異動主檔'!$D:$D,A37,'01_異動主檔'!$E:$E,"減列") | H37: =-SUMIFS('01_異動主檔'!$F:$F,'01_異動主檔'!$B:$B,104,'01_異動主檔'!$D:$D,A37,'01_異動主檔'!$E:$E,"精簡") | I37: =C37+D37+E37+F37+G37+H37
A38: 會計處 | B38: 105 | C38: =I37 | D38: =SUMIFS('01_異動主檔'!$F:$F,'01_異動主檔'!$B:$B,105,'01_異動主檔'!$D:$D,A38,'01_異動主檔'!$E:$E,"移入") | E38: =-SUMIFS('01_異動主檔'!$F:$F,'01_異動主檔'!$B:$B,105,'01_異動主檔'!$D:$D,A38,'01_異動主檔'!$E:$E,"移出") | F38: =SUMIFS('01_異動主檔'!$F:$F,'01_異動主檔'!$B:$B,105,'01_異動主檔'!$D:$D,A38,'01_異動主檔'!$E:$E,"新增") | G38: =-SUMIFS('01_異動主檔'!$F:$F,'01_異動主檔'!$B:$B,105,'01_異動主檔'!$D:$D,A38,'01_異動主檔'!$E:$E,"減列") | H38: =-SUMIFS('01_異動主檔'!$F:$F,'01_異動主檔'!$B:$B,105,'01_異動主檔'!$D:$D,A38,'01_異動主檔'!$E:$E,"精簡") | I38: =C38+D38+E38+F38+G38+H38
A39: 會計處 | B39: 106 | C39: =I38 | D39: =SUMIFS('01_異動主檔'!$F:$F,'01_異動主檔'!$B:$B,106,'01_異動主檔'!$D:$D,A39,'01_異動主檔'!$E:$E,"移入") | E39: =-SUMIFS('01_異動主檔'!$F:$F,'01_異動主檔'!$B:$B,106,'01_異動主檔'!$D:$D,A39,'01_異動主檔'!$E:$E,"移出") | F39: =SUMIFS('01_異動主檔'!$F:$F,'01_異動主檔'!$B:$B,106,'01_異動主檔'!$D:$D,A39,'01_異動主檔'!$E:$E,"新增") | G39: =-SUMIFS('01_異動主檔'!$F:$F,'01_異動主檔'!$B:$B,106,'01_異動主檔'!$D:$D,A39,'01_異動主檔'!$E:$E,"減列") | H39: =-SUMIFS('01_異動主檔'!$F:$F,'01_異動主檔'!$B:$B,106,'01_異動主檔'!$D:$D,A39,'01_異動主檔'!$E:$E,"精簡") | I39: =C39+D39+E39+F39+G39+H39
A40: 會計處 | B40: 107 | C40: =I39 | D40: =SUMIFS('01_異動主檔'!$F:$F,'01_異動主檔'!$B:$B,107,'01_異動主檔'!$D:$D,A40,'01_異動主檔'!$E:$E,"移入") | E40: =-SUMIFS('01_異動主檔'!$F:$F,'01_異動主檔'!$B:$B,107,'01_異動主檔'!$D:$D,A40,'01_異動主檔'!$E:$E,"移出") | F40: =SUMIFS('01_異動主檔'!$F:$F,'01_異動主檔'!$B:$B,107,'01_異動主檔'!$D:$D,A40,'01_異動主檔'!$E:$E,"新增") | G40: =-SUMIFS('01_異動主檔'!$F:$F,'01_異動主檔'!$B:$B,107,'01_異動主檔'!$D:$D,A40,'01_異動主檔'!$E:$E,"減列") | H40: =-SUMIFS('01_異動主檔'!$F:$F,'01_異動主檔'!$B:$B,107,'01_異動主檔'!$D:$D,A40,'01_異動主檔'!$E:$E,"精簡") | I40: =C40+D40+E40+F40+G40+H40
A41: 會計處 | B41: 108 | C41: =I40 | D41: =SUMIFS('01_異動主檔'!$F:$F,'01_異動主檔'!$B:$B,108,'01_異動主檔'!$D:$D,A41,'01_異動主檔'!$E:$E,"移入") | E41: =-SUMIFS('01_異動主檔'!$F:$F,'01_異動主檔'!$B:$B,108,'01_異動主檔'!$D:$D,A41,'01_異動主檔'!$E:$E,"移出") | F41: =SUMIFS('01_異動主檔'!$F:$F,'01_異動主檔'!$B:$B,108,'01_異動主檔'!$D:$D,A41,'01_異動主檔'!$E:$E,"新增") | G41: =-SUMIFS('01_異動主檔'!$F:$F,'01_異動主檔'!$B:$B,108,'01_異動主檔'!$D:$D,A41,'01_異動主檔'!$E:$E,"減列") | H41: =-SUMIFS('01_異動主檔'!$F:$F,'01_異動主檔'!$B:$B,108,'01_異動主檔'!$D:$D,A41,'01_異動主檔'!$E:$E,"精簡") | I41: =C41+D41+E41+F41+G41+H41
...

Sheet 02_年初員額設定
A1: 📊 年初員額設定（99年度請手動輸入，100年度起公式自動帶入）
A2: ※ 黃色格子=需手動輸入｜綠色格子=公式自動計算（請勿修改）｜只有機關名稱，沒有代碼
A4: 機關名稱 | B4: 99年 | C4: 100年 | D4: 101年 | E4: 102年 | F4: 103年 | G4: 104年 | H4: 105年 | I4: 106年 | J4: 107年 | K4: 108年 | L4: 109年 | M4: 110年 | N4: 111年 | O4: 112年 | P4: 113年 | Q4: 114年 | R4: 115年 | S4: 116年 | T4: 117年 | U4: 118年 | V4: 119年 | W4: 120年 | X4: 121年 | Y4: 122年 | Z4: 123年 | AA4: 124年 | AB4: 125年
A5: 人事處 | B5: 50 | C5: ='03_年度彙總'!C6 | D5: ='03_年度彙總'!C7 | E5: ='03_年度彙總'!C8 | F5: ='03_年度彙總'!C9 | G5: ='03_年度彙總'!C10 | H5: ='03_年度彙總'!C11 | I5: ='03_年度彙總'!C12 | J5: ='03_年度彙總'!C13 | K5: ='03_年度彙總'!C14 | L5: ='03_年度彙總'!C15 | M5: ='03_年度彙總'!C16 | N5: ='03_年度彙總'!C17 | O5: ='03_年度彙總'!C18 | P5: ='03_年度彙總'!C19 | Q5: ='03_年度彙總'!C20 | R5: ='03_年度彙總'!C21 | S5: ='03_年度彙總'!C22 | T5: ='03_年度彙總'!C23 | U5: ='03_年度彙總'!C24 | V5: ='03_年度彙總'!C25 | W5: ='03_年度彙總'!C26 | X5: ='03_年度彙總'!C27 | Y5: ='03_年度彙總'!C28 | Z5: ='03_年度彙總'!C29 | AA5: ='03_年度彙總'!C30 | AB5: ='03_年度彙總'!C31
A6: 會計處 | B6: 53 | C6: ='03_年度彙總'!C33 | D6: ='03_年度彙總'!C34 | E6: ='03_年度彙總'!C35 | F6: ='03_年度彙總'!C36 | G6: ='03_年度彙總'!C37 | H6: ='03_年度彙總'!C38 | I6: ='03_年度彙總'!C39 | J6: ='03_年度彙總'!C40 | K6: ='03_年度彙總'!C41 | L6: ='03_年度彙總'!C42 | M6: ='03_年度彙總'!C43 | N6: ='03_年度彙總'!C44 | O6: ='03_年度彙總'!C45 | P6: ='03_年度彙總'!C46 | Q6: ='03_年度彙總'!C47 | R6: ='03_年度彙總'!C48 | S6: ='03_年度彙總'!C49 | T6: ='03_年度彙總'!C50 | U6: ='03_年度彙總'!C51 | V6: ='03_年度彙總'!C52 | W6: ='03_年度彙總'!C53 | X6: ='03_年度彙總'!C54 | Y6: ='03_年度彙總'!C55 | Z6: ='03_年度彙總'!C56 | AA6: ='03_年度彙總'!C57 | AB6: ='03_年度彙總'!C58
A7: 政風處 | B7: 56 | C7: ='03_年度彙總'!C60 | D7: ='03_年度彙總'!C61 | E7: ='03_年度彙總'!C62 | F7: ='03_年度彙總'!C63 | G7: ='03_年度彙總'!C64 | H7: ='03_年度彙總'!C65 | I7: ='03_年度彙總'!C66 | J7: ='03_年度彙總'!C67 | K7: ='03_年度彙總'!C68 | L7: ='03_年度彙總'!C69 | M7: ='03_年度彙總'!C70 | N7: ='03_年度彙總'!C71 | O7: ='03_年度彙總'!C72 | P7: ='03_年度彙總'!C73 | Q7: ='03_年度彙總'!C74 | R7: ='03_年度彙總'!C75 | S7: ='03_年度彙總'!C76 | T7: ='03_年度彙總'!C77 | U7: ='03_年度彙總'!C78 | V7: ='03_年度彙總'!C79 | W7: ='03_年度彙總'!C80 | X7: ='03_年度彙總'!C81 | Y7: ='03_年度彙總'!C82 | Z7: ='03_年度彙總'!C83 | AA7: ='03_年度彙總'!C84 | AB7: ='03_年度彙總'!C85
A8: 總務處 | B8: 59 | C8: ='03_年度彙總'!C87 | D8: ='03_年度彙總'!C88 | E8: ='03_年度彙總'!C89 | F8: ='03_年度彙總'!C90 | G8: ='03_年度彙總'!C91 | H8: ='03_年度彙總'!C92 | I8: ='03_年度彙總'!C93 | J8: ='03_年度彙總'!C94 | K8: ='03_年度彙總'!C95 | L8: ='03_年度彙總'!C96 | M8: ='03_年度彙總'!C97 | N8: ='03_年度彙總'!C98 | O8: ='03_年度彙總'!C99 | P8: ='03_年度彙總'!C100 | Q8: ='03_年度彙總'!C101 | R8: ='03_年度彙總'!C102 | S8: ='03_年度彙總'!C103 | T8: ='03_年度彙總'!C104 | U8: ='03_年度彙總'!C105 | V8: ='03_年度彙總'!C106 | W8: ='03_年度彙總'!C107 | X8: ='03_年度彙總'!C108 | Y8: ='03_年度彙總'!C109 | Z8: ='03_年度彙總'!C110 | AA8: ='03_年度彙總'!C111 | AB8: ='03_年度彙總'!C112
A9: 資訊處 | B9: 62 | C9: ='03_年度彙總'!C114 | D9: ='03_年度彙總'!C115 | E9: ='03_年度彙總'!C116 | F9: ='03_年度彙總'!C117 | G9: ='03_年度彙總'!C118 | H9: ='03_年度彙總'!C119 | I9: ='03_年度彙總'!C120 | J9: ='03_年度彙總'!C121 | K9: ='03_年度彙總'!C122 | L9: ='03_年度彙總'!C123 | M9: ='03_年度彙總'!C124 | N9: ='03_年度彙總'!C125 | O9: ='03_年度彙總'!C126 | P9: ='03_年度彙總'!C127 | Q9: ='03_年度彙總'!C128 | R9: ='03_年度彙總'!C129 | S9: ='03_年度彙總'!C130 | T9: ='03_年度彙總'!C131 | U9: ='03_年度彙總'!C132 | V9: ='03_年度彙總'!C133 | W9: ='03_年度彙總'!C134 | X9: ='03_年度彙總'!C135 | Y9: ='03_年度彙總'!C136 | Z9: ='03_年度彙總'!C137 | AA9: ='03_年度彙總'!C138 | AB9: ='03_年度彙總'!C139
A10: 法制處 | B10: 65 | C10: ='03_年度彙總'!C141 | D10: ='03_年度彙總'!C142 | E10: ='03_年度彙總'!C143 | F10: ='03_年度彙總'!C144 | G10: ='03_年度彙總'!C145 | H10: ='03_年度彙總'!C146 | I10: ='03_年度彙總'!C147 | J10: ='03_年度彙總'!C148 | K10: ='03_年度彙總'!C149 | L10: ='03_年度彙總'!C150 | M10: ='03_年度彙總'!C151 | N10: ='03_年度彙總'!C152 | O10: ='03_年度彙總'!C153 | P10: ='03_年度彙總'!C154 | Q10: ='03_年度彙總'!C155 | R10: ='03_年度彙總'!C156 | S10: ='03_年度彙總'!C157 | T10: ='03_年度彙總'!C158 | U10: ='03_年度彙總'!C159 | V10: ='03_年度彙總'!C160 | W10: ='03_年度彙總'!C161 | X10: ='03_年度彙總'!C162 | Y10: ='03_年度彙總'!C163 | Z10: ='03_年度彙總'!C164 | AA10: ='03_年度彙總'!C165 | AB10: ='03_年度彙總'!C166
A11: 秘書處 | B11: 68 | C11: ='03_年度彙總'!C168 | D11: ='03_年度彙總'!C169 | E11: ='03_年度彙總'!C170 | F11: ='03_年度彙總'!C171 | G11: ='03_年度彙總'!C172 | H11: ='03_年度彙總'!C173 | I11: ='03_年度彙總'!C174 | J11: ='03_年度彙總'!C175 | K11: ='03_年度彙總'!C176 | L11: ='03_年度彙總'!C177 | M11: ='03_年度彙總'!C178 | N11: ='03_年度彙總'!C179 | O11: ='03_年度彙總'!C180 | P11: ='03_年度彙總'!C181 | Q11: ='03_年度彙總'!C182 | R11: ='03_年度彙總'!C183 | S11: ='03_年度彙總'!C184 | T11: ='03_年度彙總'!C185 | U11: ='03_年度彙總'!C186 | V11: ='03_年度彙總'!C187 | W11: ='03_年度彙總'!C188 | X11: ='03_年度彙總'!C189 | Y11: ='03_年度彙總'!C190 | Z11: ='03_年度彙總'!C191 | AA11: ='03_年度彙總'!C192 | AB11: ='03_年度彙總'!C193
A12: 公關室 | B12: 71 | C12: ='03_年度彙總'!C195 | D12: ='03_年度彙總'!C196 | E12: ='03_年度彙總'!C197 | F12: ='03_年度彙總'!C198 | G12: ='03_年度彙總'!C199 | H12: ='03_年度彙總'!C200 | I12: ='03_年度彙總'!C201 | J12: ='03_年度彙總'!C202 | K12: ='03_年度彙總'!C203 | L12: ='03_年度彙總'!C204 | M12: ='03_年度彙總'!C205 | N12: ='03_年度彙總'!C206 | O12: ='03_年度彙總'!C207 | P12: ='03_年度彙總'!C208 | Q12: ='03_年度彙總'!C209 | R12: ='03_年度彙總'!C210 | S12: ='03_年度彙總'!C211 | T12: ='03_年度彙總'!C212 | U12: ='03_年度彙總'!C213 | V12: ='03_年度彙總'!C214 | W12: ='03_年度彙總'!C215 | X12: ='03_年度彙總'!C216 | Y12: ='03_年度彙總'!C217 | Z12: ='03_年度彙總'!C218 | AA12: ='03_年度彙總'!C219 | AB12: ='03_年度彙總'!C220
A13: 第一組 | B13: 74 | C13: ='03_年度彙總'!C222 | D13: ='03_年度彙總'!C223 | E13: ='03_年度彙總'!C224 | F13: ='03_年度彙總'!C225 | G13: ='03_年度彙總'!C226 | H13: ='03_年度彙總'!C227 | I13: ='03_年度彙總'!C228 | J13: ='03_年度彙總'!C229 | K13: ='03_年度彙總'!C230 | L13: ='03_年度彙總'!C231 | M13: ='03_年度彙總'!C232 | N13: ='03_年度彙總'!C233 | O13: ='03_年度彙總'!C234 | P13: ='03_年度彙總'!C235 | Q13: ='03_年度彙總'!C236 | R13: ='03_年度彙總'!C237 | S13: ='03_年度彙總'!C238 | T13: ='03_年度彙總'!C239 | U13: ='03_年度彙總'!C240 | V13: ='03_年度彙總'!C241 | W13: ='03_年度彙總'!C242 | X13: ='03_年度彙總'!C243 | Y13: ='03_年度彙總'!C244 | Z13: ='03_年度彙總'!C245 | AA13: ='03_年度彙總'!C246 | AB13: ='03_年度彙總'!C247
A14: 第二組 | B14: 77 | C14: ='03_年度彙總'!C249 | D14: ='03_年度彙總'!C250 | E14: ='03_年度彙總'!C251 | F14: ='03_年度彙總'!C252 | G14: ='03_年度彙總'!C253 | H14: ='03_年度彙總'!C254 | I14: ='03_年度彙總'!C255 | J14: ='03_年度彙總'!C256 | K14: ='03_年度彙總'!C257 | L14: ='03_年度彙總'!C258 | M14: ='03_年度彙總'!C259 | N14: ='03_年度彙總'!C260 | O14: ='03_年度彙總'!C261 | P14: ='03_年度彙總'!C262 | Q14: ='03_年度彙總'!C263 | R14: ='03_年度彙總'!C264 | S14: ='03_年度彙總'!C265 | T14: ='03_年度彙總'!C266 | U14: ='03_年度彙總'!C267 | V14: ='03_年度彙總'!C268 | W14: ='03_年度彙總'!C269 | X14: ='03_年度彙總'!C270 | Y14: ='03_年度彙總'!C271 | Z14: ='03_年度彙總'!C272 | AA14: ='03_年度彙總'!C273 | AB14: ='03_年度彙總'!C274
A15: 第三組 | B15: 80 | C15: ='03_年度彙總'!C276 | D15: ='03_年度彙總'!C277 | E15: ='03_年度彙總'!C278 | F15: ='03_年度彙總'!C279 | G15: ='03_年度彙總'!C280 | H15: ='03_年度彙總'!C281 | I15: ='03_年度彙總'!C282 | J15: ='03_年度彙總'!C283 | K15: ='03_年度彙總'!C284 | L15: ='03_年度彙總'!C285 | M15: ='03_年度彙總'!C286 | N15: ='03_年度彙總'!C287 | O15: ='03_年度彙總'!C288 | P15: ='03_年度彙總'!C289 | Q15: ='03_年度彙總'!C290 | R15: ='03_年度彙總'!C291 | S15: ='03_年度彙總'!C292 | T15: ='03_年度彙總'!C293 | U15: ='03_年度彙總'!C294 | V15: ='03_年度彙總'!C295 | W15: ='03_年度彙總'!C296 | X15: ='03_年度彙總'!C297 | Y15: ='03_年度彙總'!C298 | Z15: ='03_年度彙總'!C299 | AA15: ='03_年度彙總'!C300 | AB15: ='03_年度彙總'!C301
A16: 第四組 | B16: 83 | C16: ='03_年度彙總'!C303 | D16: ='03_年度彙總'!C304 | E16: ='03_年度彙總'!C305 | F16: ='03_年度彙總'!C306 | G16: ='03_年度彙總'!C307 | H16: ='03_年度彙總'!C308 | I16: ='03_年度彙總'!C309 | J16: ='03_年度彙總'!C310 | K16: ='03_年度彙總'!C311 | L16: ='03_年度彙總'!C312 | M16: ='03_年度彙總'!C313 | N16: ='03_年度彙總'!C314 | O16: ='03_年度彙總'!C315 | P16: ='03_年度彙總'!C316 | Q16: ='03_年度彙總'!C317 | R16: ='03_年度彙總'!C318 | S16: ='03_年度彙總'!C319 | T16: ='03_年度彙總'!C320 | U16: ='03_年度彙總'!C321 | V16: ='03_年度彙總'!C322 | W16: ='03_年度彙總'!C323 | X16: ='03_年度彙總'!C324 | Y16: ='03_年度彙總'!C325 | Z16: ='03_年度彙總'!C326 | AA16: ='03_年度彙總'!C327 | AB16: ='03_年度彙總'!C328
A17: 第五組 | B17: 86 | C17: ='03_年度彙總'!C330 | D17: ='03_年度彙總'!C331 | E17: ='03_年度彙總'!C332 | F17: ='03_年度彙總'!C333 | G17: ='03_年度彙總'!C334 | H17: ='03_年度彙總'!C335 | I17: ='03_年度彙總'!C336 | J17: ='03_年度彙總'!C337 | K17: ='03_年度彙總'!C338 | L17: ='03_年度彙總'!C339 | M17: ='03_年度彙總'!C340 | N17: ='03_年度彙總'!C341 | O17: ='03_年度彙總'!C342 | P17: ='03_年度彙總'!C343 | Q17: ='03_年度彙總'!C344 | R17: ='03_年度彙總'!C345 | S17: ='03_年度彙總'!C346 | T17: ='03_年度彙總'!C347 | U17: ='03_年度彙總'!C348 | V17: ='03_年度彙總'!C349 | W17: ='03_年度彙總'!C350 | X17: ='03_年度彙總'!C351 | Y17: ='03_年度彙總'!C352 | Z17: ='03_年度彙總'!C353 | AA17: ='03_年度彙總'!C354 | AB17: ='03_年度彙總'!C355
A18: 第六組 | B18: 89 | C18: ='03_年度彙總'!C357 | D18: ='03_年度彙總'!C358 | E18: ='03_年度彙總'!C359 | F18: ='03_年度彙總'!C360 | G18: ='03_年度彙總'!C361 | H18: ='03_年度彙總'!C362 | I18: ='03_年度彙總'!C363 | J18: ='03_年度彙總'!C364 | K18: ='03_年度彙總'!C365 | L18: ='03_年度彙總'!C366 | M18: ='03_年度彙總'!C367 | N18: ='03_年度彙總'!C368 | O18: ='03_年度彙總'!C369 | P18: ='03_年度彙總'!C370 | Q18: ='03_年度彙總'!C371 | R18: ='03_年度彙總'!C372 | S18: ='03_年度彙總'!C373 | T18: ='03_年度彙總'!C374 | U18: ='03_年度彙總'!C375 | V18: ='03_年度彙總'!C376 | W18: ='03_年度彙總'!C377 | X18: ='03_年度彙總'!C378 | Y18: ='03_年度彙總'!C379 | Z18: ='03_年度彙總'!C380 | AA18: ='03_年度彙總'!C381 | AB18: ='03_年度彙總'!C382
A19: 第七組 | B19: 92 | C19: ='03_年度彙總'!C384 | D19: ='03_年度彙總'!C385 | E19: ='03_年度彙總'!C386 | F19: ='03_年度彙總'!C387 | G19: ='03_年度彙總'!C388 | H19: ='03_年度彙總'!C389 | I19: ='03_年度彙總'!C390 | J19: ='03_年度彙總'!C391 | K19: ='03_年度彙總'!C392 | L19: ='03_年度彙總'!C393 | M19: ='03_年度彙總'!C394 | N19: ='03_年度彙總'!C395 | O19: ='03_年度彙總'!C396 | P19: ='03_年度彙總'!C397 | Q19: ='03_年度彙總'!C398 | R19: ='03_年度彙總'!C399 | S19: ='03_年度彙總'!C400 | T19: ='03_年度彙總'!C401 | U19: ='03_年度彙總'!C402 | V19: ='03_年度彙總'!C403 | W19: ='03_年度彙總'!C404 | X19: ='03_年度彙總'!C405 | Y19: ='03_年度彙總'!C406 | Z19: ='03_年度彙總'!C407 | AA19: ='03_年度彙總'!C408 | AB19: ='03_年度彙總'!C409
A20: 第八組 | C20: ='03_年度彙總'!C411 | D20: ='03_年度彙總'!C412 | E20: ='03_年度彙總'!C413 | F20: ='03_年度彙總'!C414 | G20: ='03_年度彙總'!C415 | H20: ='03_年度彙總'!C416 | I20: ='03_年度彙總'!C417 | J20: ='03_年度彙總'!C418 | K20: ='03_年度彙總'!C419 | L20: ='03_年度彙總'!C420 | M20: ='03_年度彙總'!C421 | N20: ='03_年度彙總'!C422 | O20: ='03_年度彙總'!C423 | P20: ='03_年度彙總'!C424 | Q20: ='03_年度彙總'!C425 | R20: ='03_年度彙總'!C426 | S20: ='03_年度彙總'!C427 | T20: ='03_年度彙總'!C428 | U20: ='03_年度彙總'!C429 | V20: ='03_年度彙總'!C430 | W20: ='03_年度彙總'!C431 | X20: ='03_年度彙總'!C432 | Y20: ='03_年度彙總'!C433 | Z20: ='03_年度彙總'!C434 | AA20: ='03_年度彙總'!C435 | AB20: ='03_年度彙總'!C436
A21: 台北分局 | C21: ='03_年度彙總'!C438 | D21: ='03_年度彙總'!C439 | E21: ='03_年度彙總'!C440 | F21: ='03_年度彙總'!C441 | G21: ='03_年度彙總'!C442 | H21: ='03_年度彙總'!C443 | I21: ='03_年度彙總'!C444 | J21: ='03_年度彙總'!C445 | K21: ='03_年度彙總'!C446 | L21: ='03_年度彙總'!C447 | M21: ='03_年度彙總'!C448 | N21: ='03_年度彙總'!C449 | O21: ='03_年度彙總'!C450 | P21: ='03_年度彙總'!C451 | Q21: ='03_年度彙總'!C452 | R21: ='03_年度彙總'!C453 | S21: ='03_年度彙總'!C454 | T21: ='03_年度彙總'!C455 | U21: ='03_年度彙總'!C456 | V21: ='03_年度彙總'!C457 | W21: ='03_年度彙總'!C458 | X21: ='03_年度彙總'!C459 | Y21: ='03_年度彙總'!C460 | Z21: ='03_年度彙總'!C461 | AA21: ='03_年度彙總'!C462 | AB21: ='03_年度彙總'!C463
A22: 新北分局 | C22: ='03_年度彙總'!C465 | D22: ='03_年度彙總'!C466 | E22: ='03_年度彙總'!C467 | F22: ='03_年度彙總'!C468 | G22: ='03_年度彙總'!C469 | H22: ='03_年度彙總'!C470 | I22: ='03_年度彙總'!C471 | J22: ='03_年度彙總'!C472 | K22: ='03_年度彙總'!C473 | L22: ='03_年度彙總'!C474 | M22: ='03_年度彙總'!C475 | N22: ='03_年度彙總'!C476 | O22: ='03_年度彙總'!C477 | P22: ='03_年度彙總'!C478 | Q22: ='03_年度彙總'!C479 | R22: ='03_年度彙總'!C480 | S22: ='03_年度彙總'!C481 | T22: ='03_年度彙總'!C482 | U22: ='03_年度彙總'!C483 | V22: ='03_年度彙總'!C484 | W22: ='03_年度彙總'!C485 | X22: ='03_年度彙總'!C486 | Y22: ='03_年度彙總'!C487 | Z22: ='03_年度彙總'!C488 | AA22: ='03_年度彙總'!C489 | AB22: ='03_年度彙總'!C490
A23: 桃園分局 | C23: ='03_年度彙總'!C492 | D23: ='03_年度彙總'!C493 | E23: ='03_年度彙總'!C494 | F23: ='03_年度彙總'!C495 | G23: ='03_年度彙總'!C496 | H23: ='03_年度彙總'!C497 | I23: ='03_年度彙總'!C498 | J23: ='03_年度彙總'!C499 | K23: ='03_年度彙總'!C500 | L23: ='03_年度彙總'!C501 | M23: ='03_年度彙總'!C502 | N23: ='03_年度彙總'!C503 | O23: ='03_年度彙總'!C504 | P23: ='03_年度彙總'!C505 | Q23: ='03_年度彙總'!C506 | R23: ='03_年度彙總'!C507 | S23: ='03_年度彙總'!C508 | T23: ='03_年度彙總'!C509 | U23: ='03_年度彙總'!C510 | V23: ='03_年度彙總'!C511 | W23: ='03_年度彙總'!C512 | X23: ='03_年度彙總'!C513 | Y23: ='03_年度彙總'!C514 | Z23: ='03_年度彙總'!C515 | AA23: ='03_年度彙總'!C516 | AB23: ='03_年度彙總'!C517
A24: 台中分局 | C24: ='03_年度彙總'!C519 | D24: ='03_年度彙總'!C520 | E24: ='03_年度彙總'!C521 | F24: ='03_年度彙總'!C522 | G24: ='03_年度彙總'!C523 | H24: ='03_年度彙總'!C524 | I24: ='03_年度彙總'!C525 | J24: ='03_年度彙總'!C526 | K24: ='03_年度彙總'!C527 | L24: ='03_年度彙總'!C528 | M24: ='03_年度彙總'!C529 | N24: ='03_年度彙總'!C530 | O24: ='03_年度彙總'!C531 | P24: ='03_年度彙總'!C532 | Q24: ='03_年度彙總'!C533 | R24: ='03_年度彙總'!C534 | S24: ='03_年度彙總'!C535 | T24: ='03_年度彙總'!C536 | U24: ='03_年度彙總'!C537 | V24: ='03_年度彙總'!C538 | W24: ='03_年度彙總'!C539 | X24: ='03_年度彙總'!C540 | Y24: ='03_年度彙總'!C541 | Z24: ='03_年度彙總'!C542 | AA24: ='03_年度彙總'!C543 | AB24: ='03_年度彙總'!C544
A25: 台南分局 | C25: ='03_年度彙總'!C546 | D25: ='03_年度彙總'!C547 | E25: ='03_年度彙總'!C548 | F25: ='03_年度彙總'!C549 | G25: ='03_年度彙總'!C550 | H25: ='03_年度彙總'!C551 | I25: ='03_年度彙總'!C552 | J25: ='03_年度彙總'!C553 | K25: ='03_年度彙總'!C554 | L25: ='03_年度彙總'!C555 | M25: ='03_年度彙總'!C556 | N25: ='03_年度彙總'!C557 | O25: ='03_年度彙總'!C558 | P25: ='03_年度彙總'!C559 | Q25: ='03_年度彙總'!C560 | R25: ='03_年度彙總'!C561 | S25: ='03_年度彙總'!C562 | T25: ='03_年度彙總'!C563 | U25: ='03_年度彙總'!C564 | V25: ='03_年度彙總'!C565 | W25: ='03_年度彙總'!C566 | X25: ='03_年度彙總'!C567 | Y25: ='03_年度彙總'!C568 | Z25: ='03_年度彙總'!C569 | AA25: ='03_年度彙總'!C570 | AB25: ='03_年度彙總'!C571
A26: 高雄分局 | C26: ='03_年度彙總'!C573 | D26: ='03_年度彙總'!C574 | E26: ='03_年度彙總'!C575 | F26: ='03_年度彙總'!C576 | G26: ='03_年度彙總'!C577 | H26: ='03_年度彙總'!C578 | I26: ='03_年度彙總'!C579 | J26: ='03_年度彙總'!C580 | K26: ='03_年度彙總'!C581 | L26: ='03_年度彙總'!C582 | M26: ='03_年度彙總'!C583 | N26: ='03_年度彙總'!C584 | O26: ='03_年度彙總'!C585 | P26: ='03_年度彙總'!C586 | Q26: ='03_年度彙總'!C587 | R26: ='03_年度彙總'!C588 | S26: ='03_年度彙總'!C589 | T26: ='03_年度彙總'!C590 | U26: ='03_年度彙總'!C591 | V26: ='03_年度彙總'!C592 | W26: ='03_年度彙總'!C593 | X26: ='03_年度彙總'!C594 | Y26: ='03_年度彙總'!C595 | Z26: ='03_年度彙總'!C596 | AA26: ='03_年度彙總'!C597 | AB26: ='03_年度彙總'!C598
A27: 基隆分局 | C27: ='03_年度彙總'!C600 | D27: ='03_年度彙總'!C601 | E27: ='03_年度彙總'!C602 | F27: ='03_年度彙總'!C603 | G27: ='03_年度彙總'!C604 | H27: ='03_年度彙總'!C605 | I27: ='03_年度彙總'!C606 | J27: ='03_年度彙總'!C607 | K27: ='03_年度彙總'!C608 | L27: ='03_年度彙總'!C609 | M27: ='03_年度彙總'!C610 | N27: ='03_年度彙總'!C611 | O27: ='03_年度彙總'!C612 | P27: ='03_年度彙總'!C613 | Q27: ='03_年度彙總'!C614 | R27: ='03_年度彙總'!C615 | S27: ='03_年度彙總'!C616 | T27: ='03_年度彙總'!C617 | U27: ='03_年度彙總'!C618 | V27: ='03_年度彙總'!C619 | W27: ='03_年度彙總'!C620 | X27: ='03_年度彙總'!C621 | Y27: ='03_年度彙總'!C622 | Z27: ='03_年度彙總'!C623 | AA27: ='03_年度彙總'!C624 | AB27: ='03_年度彙總'!C625
A28: 花蓮分局 | C28: ='03_年度彙總'!C627 | D28: ='03_年度彙總'!C628 | E28: ='03_年度彙總'!C629 | F28: ='03_年度彙總'!C630 | G28: ='03_年度彙總'!C631 | H28: ='03_年度彙總'!C632 | I28: ='03_年度彙總'!C633 | J28: ='03_年度彙總'!C634 | K28: ='03_年度彙總'!C635 | L28: ='03_年度彙總'!C636 | M28: ='03_年度彙總'!C637 | N28: ='03_年度彙總'!C638 | O28: ='03_年度彙總'!C639 | P28: ='03_年度彙總'!C640 | Q28: ='03_年度彙總'!C641 | R28: ='03_年度彙總'!C642 | S28: ='03_年度彙總'!C643 | T28: ='03_年度彙總'!C644 | U28: ='03_年度彙總'!C645 | V28: ='03_年度彙總'!C646 | W28: ='03_年度彙總'!C647 | X28: ='03_年度彙總'!C648 | Y28: ='03_年度彙總'!C649 | Z28: ='03_年度彙總'!C650 | AA28: ='03_年度彙總'!C651 | AB28: ='03_年度彙總'!C652
A29: 綜合規劃科 | C29: ='03_年度彙總'!C654 | D29: ='03_年度彙總'!C655 | E29: ='03_年度彙總'!C656 | F29: ='03_年度彙總'!C657 | G29: ='03_年度彙總'!C658 | H29: ='03_年度彙總'!C659 | I29: ='03_年度彙總'!C660 | J29: ='03_年度彙總'!C661 | K29: ='03_年度彙總'!C662 | L29: ='03_年度彙總'!C663 | M29: ='03_年度彙總'!C664 | N29: ='03_年度彙總'!C665 | O29: ='03_年度彙總'!C666 | P29: ='03_年度彙總'!C667 | Q29: ='03_年度彙總'!C668 | R29: ='03_年度彙總'!C669 | S29: ='03_年度彙總'!C670 | T29: ='03_年度彙總'!C671 | U29: ='03_年度彙總'!C672 | V29: ='03_年度彙總'!C673 | W29: ='03_年度彙總'!C674 | X29: ='03_年度彙總'!C675 | Y29: ='03_年度彙總'!C676 | Z29: ='03_年度彙總'!C677 | AA29: ='03_年度彙總'!C678 | AB29: ='03_年度彙總'!C679
A30: 歲計科 | C30: ='03_年度彙總'!C681 | D30: ='03_年度彙總'!C682 | E30: ='03_年度彙總'!C683 | F30: ='03_年度彙總'!C684 | G30: ='03_年度彙總'!C685 | H30: ='03_年度彙總'!C686 | I30: ='03_年度彙總'!C687 | J30: ='03_年度彙總'!C688 | K30: ='03_年度彙總'!C689 | L30: ='03_年度彙總'!C690 | M30: ='03_年度彙總'!C691 | N30: ='03_年度彙總'!C692 | O30: ='03_年度彙總'!C693 | P30: ='03_年度彙總'!C694 | Q30: ='03_年度彙總'!C695 | R30: ='03_年度彙總'!C696 | S30: ='03_年度彙總'!C697 | T30: ='03_年度彙總'!C698 | U30: ='03_年度彙總'!C699 | V30: ='03_年度彙總'!C700 | W30: ='03_年度彙總'!C701 | X30: ='03_年度彙總'!C702 | Y30: ='03_年度彙總'!C703 | Z30: ='03_年度彙總'!C704 | AA30: ='03_年度彙總'!C705 | AB30: ='03_年度彙總'!C706
A31: 統計科 | C31: ='03_年度彙總'!C708 | D31: ='03_年度彙總'!C709 | E31: ='03_年度彙總'!C710 | F31: ='03_年度彙總'!C711 | G31: ='03_年度彙總'!C712 | H31: ='03_年度彙總'!C713 | I31: ='03_年度彙總'!C714 | J31: ='03_年度彙總'!C715 | K31: ='03_年度彙總'!C716 | L31: ='03_年度彙總'!C717 | M31: ='03_年度彙總'!C718 | N31: ='03_年度彙總'!C719 | O31: ='03_年度彙總'!C720 | P31: ='03_年度彙總'!C721 | Q31: ='03_年度彙總'!C722 | R31: ='03_年度彙總'!C723 | S31: ='03_年度彙總'!C724 | T31: ='03_年度彙總'!C725 | U31: ='03_年度彙總'!C726 | V31: ='03_年度彙總'!C727 | W31: ='03_年度彙總'!C728 | X31: ='03_年度彙總'!C729 | Y31: ='03_年度彙總'!C730 | Z31: ='03_年度彙總'!C731 | AA31: ='03_年度彙總'!C732 | AB31: ='03_年度彙總'!C733
A32: 文書科 | C32: ='03_年度彙總'!C735 | D32: ='03_年度彙總'!C736 | E32: ='03_年度彙總'!C737 | F32: ='03_年度彙總'!C738 | G32: ='03_年度彙總'!C739 | H32: ='03_年度彙總'!C740 | I32: ='03_年度彙總'!C741 | J32: ='03_年度彙總'!C742 | K32: ='03_年度彙總'!C743 | L32: ='03_年度彙總'!C744 | M32: ='03_年度彙總'!C745 | N32: ='03_年度彙總'!C746 | O32: ='03_年度彙總'!C747 | P32: ='03_年度彙總'!C748 | Q32: ='03_年度彙總'!C749 | R32: ='03_年度彙總'!C750 | S32: ='03_年度彙總'!C751 | T32: ='03_年度彙總'!C752 | U32: ='03_年度彙總'!C753 | V32: ='03_年度彙總'!C754 | W32: ='03_年度彙總'!C755 | X32: ='03_年度彙總'!C756 | Y32: ='03_年度彙總'!C757 | Z32: ='03_年度彙總'!C758 | AA32: ='03_年度彙總'!C759 | AB32: ='03_年度彙總'!C760
A33: 出納科 | C33: ='03_年度彙總'!C762 | D33: ='03_年度彙總'!C763 | E33: ='03_年度彙總'!C764 | F33: ='03_年度彙總'!C765 | G33: ='03_年度彙總'!C766 | H33: ='03_年度彙總'!C767 | I33: ='03_年度彙總'!C768 | J33: ='03_年度彙總'!C769 | K33: ='03_年度彙總'!C770 | L33: ='03_年度彙總'!C771 | M33: ='03_年度彙總'!C772 | N33: ='03_年度彙總'!C773 | O33: ='03_年度彙總'!C774 | P33: ='03_年度彙總'!C775 | Q33: ='03_年度彙總'!C776 | R33: ='03_年度彙總'!C777 | S33: ='03_年度彙總'!C778 | T33: ='03_年度彙總'!C779 | U33: ='03_年度彙總'!C780 | V33: ='03_年度彙總'!C781 | W33: ='03_年度彙總'!C782 | X33: ='03_年度彙總'!C783 | Y33: ='03_年度彙總'!C784 | Z33: ='03_年度彙總'!C785 | AA33: ='03_年度彙總'!C786 | AB33: ='03_年度彙總'!C787
A34: 採購科 | C34: ='03_年度彙總'!C789 | D34: ='03_年度彙總'!C790 | E34: ='03_年度彙總'!C791 | F34: ='03_年度彙總'!C792 | G34: ='03_年度彙總'!C793 | H34: ='03_年度彙總'!C794 | I34: ='03_年度彙總'!C795 | J34: ='03_年度彙總'!C796 | K34: ='03_年度彙總'!C797 | L34: ='03_年度彙總'!C798 | M34: ='03_年度彙總'!C799 | N34: ='03_年度彙總'!C800 | O34: ='03_年度彙總'!C801 | P34: ='03_年度彙總'!C802 | Q34: ='03_年度彙總'!C803 | R34: ='03_年度彙總'!C804 | S34: ='03_年度彙總'!C805 | T34: ='03_年度彙總'!C806 | U34: ='03_年度彙總'!C807 | V34: ='03_年度彙總'!C808 | W34: ='03_年度彙總'!C809 | X34: ='03_年度彙總'!C810 | Y34: ='03_年度彙總'!C811 | Z34: ='03_年度彙總'!C812 | AA34: ='03_年度彙總'!C813 | AB34: ='03_年度彙總'!C814
A35: 稽查科 | C35: ='03_年度彙總'!C816 | D35: ='03_年度彙總'!C817 | E35: ='03_年度彙總'!C818 | F35: ='03_年度彙總'!C819 | G35: ='03_年度彙總'!C820 | H35: ='03_年度彙總'!C821 | I35: ='03_年度彙總'!C822 | J35: ='03_年度彙總'!C823 | K35: ='03_年度彙總'!C824 | L35: ='03_年度彙總'!C825 | M35: ='03_年度彙總'!C826 | N35: ='03_年度彙總'!C827 | O35: ='03_年度彙總'!C828 | P35: ='03_年度彙總'!C829 | Q35: ='03_年度彙總'!C830 | R35: ='03_年度彙總'!C831 | S35: ='03_年度彙總'!C832 | T35: ='03_年度彙總'!C833 | U35: ='03_年度彙總'!C834 | V35: ='03_年度彙總'!C835 | W35: ='03_年度彙總'!C836 | X35: ='03_年度彙總'!C837 | Y35: ='03_年度彙總'!C838 | Z35: ='03_年度彙總'!C839 | AA35: ='03_年度彙總'!C840 | AB35: ='03_年度彙總'!C841
A36: 核稿科 | C36: ='03_年度彙總'!C843 | D36: ='03_年度彙總'!C844 | E36: ='03_年度彙總'!C845 | F36: ='03_年度彙總'!C846 | G36: ='03_年度彙總'!C847 | H36: ='03_年度彙總'!C848 | I36: ='03_年度彙總'!C849 | J36: ='03_年度彙總'!C850 | K36: ='03_年度彙總'!C851 | L36: ='03_年度彙總'!C852 | M36: ='03_年度彙總'!C853 | N36: ='03_年度彙總'!C854 | O36: ='03_年度彙總'!C855 | P36: ='03_年度彙總'!C856 | Q36: ='03_年度彙總'!C857 | R36: ='03_年度彙總'!C858 | S36: ='03_年度彙總'!C859 | T36: ='03_年度彙總'!C860 | U36: ='03_年度彙總'!C861 | V36: ='03_年度彙總'!C862 | W36: ='03_年度彙總'!C863 | X36: ='03_年度彙總'!C864 | Y36: ='03_年度彙總'!C865 | Z36: ='03_年度彙總'!C866 | AA36: ='03_年度彙總'!C867 | AB36: ='03_年度彙總'!C868
A37: 訓練中心 | C37: ='03_年度彙總'!C870 | D37: ='03_年度彙總'!C871 | E37: ='03_年度彙總'!C872 | F37: ='03_年度彙總'!C873 | G37: ='03_年度彙總'!C874 | H37: ='03_年度彙總'!C875 | I37: ='03_年度彙總'!C876 | J37: ='03_年度彙總'!C877 | K37: ='03_年度彙總'!C878 | L37: ='03_年度彙總'!C879 | M37: ='03_年度彙總'!C880 | N37: ='03_年度彙總'!C881 | O37: ='03_年度彙總'!C882 | P37: ='03_年度彙總'!C883 | Q37: ='03_年度彙總'!C884 | R37: ='03_年度彙總'!C885 | S37: ='03_年度彙總'!C886 | T37: ='03_年度彙總'!C887 | U37: ='03_年度彙總'!C888 | V37: ='03_年度彙總'!C889 | W37: ='03_年度彙總'!C890 | X37: ='03_年度彙總'!C891 | Y37: ='03_年度彙總'!C892 | Z37: ='03_年度彙總'!C893 | AA37: ='03_年度彙總'!C894 | AB37: ='03_年度彙總'!C895
A38: 研發中心 | C38: ='03_年度彙總'!C897 | D38: ='03_年度彙總'!C898 | E38: ='03_年度彙總'!C899 | F38: ='03_年度彙總'!C900 | G38: ='03_年度彙總'!C901 | H38: ='03_年度彙總'!C902 | I38: ='03_年度彙總'!C903 | J38: ='03_年度彙總'!C904 | K38: ='03_年度彙總'!C905 | L38: ='03_年度彙總'!C906 | M38: ='03_年度彙總'!C907 | N38: ='03_年度彙總'!C908 | O38: ='03_年度彙總'!C909 | P38: ='03_年度彙總'!C910 | Q38: ='03_年度彙總'!C911 | R38: ='03_年度彙總'!C912 | S38: ='03_年度彙總'!C913 | T38: ='03_年度彙總'!C914 | U38: ='03_年度彙總'!C915 | V38: ='03_年度彙總'!C916 | W38: ='03_年度彙總'!C917 | X38: ='03_年度彙總'!C918 | Y38: ='03_年度彙總'!C919 | Z38: ='03_年度彙總'!C920 | AA38: ='03_年度彙總'!C921 | AB38: ='03_年度彙總'!C922
A39: 服務中心 | C39: ='03_年度彙總'!C924 | D39: ='03_年度彙總'!C925 | E39: ='03_年度彙總'!C926 | F39: ='03_年度彙總'!C927 | G39: ='03_年度彙總'!C928 | H39: ='03_年度彙總'!C929 | I39: ='03_年度彙總'!C930 | J39: ='03_年度彙總'!C931 | K39: ='03_年度彙總'!C932 | L39: ='03_年度彙總'!C933 | M39: ='03_年度彙總'!C934 | N39: ='03_年度彙總'!C935 | O39: ='03_年度彙總'!C936 | P39: ='03_年度彙總'!C937 | Q39: ='03_年度彙總'!C938 | R39: ='03_年度彙總'!C939 | S39: ='03_年度彙總'!C940 | T39: ='03_年度彙總'!C941 | U39: ='03_年度彙總'!C942 | V39: ='03_年度彙總'!C943 | W39: ='03_年度彙總'!C944 | X39: ='03_年度彙總'!C945 | Y39: ='03_年度彙總'!C946 | Z39: ='03_年度彙總'!C947 | AA39: ='03_年度彙總'!C948 | AB39: ='03_年度彙總'!C949
A40: 管理中心 | C40: ='03_年度彙總'!C951 | D40: ='03_年度彙總'!C952 | E40: ='03_年度彙總'!C953 | F40: ='03_年度彙總'!C954 | G40: ='03_年度彙總'!C955 | H40: ='03_年度彙總'!C956 | I40: ='03_年度彙總'!C957 | J40: ='03_年度彙總'!C958 | K40: ='03_年度彙總'!C959 | L40: ='03_年度彙總'!C960 | M40: ='03_年度彙總'!C961 | N40: ='03_年度彙總'!C962 | O40: ='03_年度彙總'!C963 | P40: ='03_年度彙總'!C964 | Q40: ='03_年度彙總'!C965 | R40: ='03_年度彙總'!C966 | S40: ='03_年度彙總'!C967 | T40: ='03_年度彙總'!C968 | U40: ='03_年度彙總'!C969 | V40: ='03_年度彙總'!C970 | W40: ='03_年度彙總'!C971 | X40: ='03_年度彙總'!C972 | Y40: ='03_年度彙總'!C973 | Z40: ='03_年度彙總'!C974 | AA40: ='03_年度彙總'!C975 | AB40: ='03_年度彙總'!C976
A41: 審查中心 | C41: ='03_年度彙總'!C978 | D41: ='03_年度彙總'!C979 | E41: ='03_年度彙總'!C980 | F41: ='03_年度彙總'!C981 | G41: ='03_年度彙總'!C982 | H41: ='03_年度彙總'!C983 | I41: ='03_年度彙總'!C984 | J41: ='03_年度彙總'!C985 | K41: ='03_年度彙總'!C986 | L41: ='03_年度彙總'!C987 | M41: ='03_年度彙總'!C988 | N41: ='03_年度彙總'!C989 | O41: ='03_年度彙總'!C990 | P41: ='03_年度彙總'!C991 | Q41: ='03_年度彙總'!C992 | R41: ='03_年度彙總'!C993 | S41: ='03_年度彙總'!C994 | T41: ='03_年度彙總'!C995 | U41: ='03_年度彙總'!C996 | V41: ='03_年度彙總'!C997 | W41: ='03_年度彙總'!C998 | X41: ='03_年度彙總'!C999 | Y41: ='03_年度彙總'!C1000 | Z41: ='03_年度彙總'!C1001 | AA41: ='03_年度彙總'!C1002 | AB41: ='03_年度彙總'!C1003
...

Sheet 04_異動明細
A1: 📋 異動明細（使用 Ctrl+Shift+L 篩選查詢）
A2: 【使用方法】
A3: 1. 選取任意資料格，按 Ctrl+Shift+L 開啟篩選
A4: 2. 點擊「機關名稱」欄的下拉箭頭，選擇要查詢的機關
A5: 3. 即可只看到該機關的所有異動記錄
A6: 4. 要取消篩選，再按一次 Ctrl+Shift+L
A7: 流水號 | B7: 年度 | C7: 修正日期 | D7: 機關名稱 | E7: 調整類型 | F7: 人數 | G7: 事由 | H7: 備註
A8: 1 | B8: 99 | C8: 99/01 | D8: 人事處 | E8: 移入 | F8: 5 | G8: 業務調整
A9: 2 | B9: 99 | C9: 99/03 | D9: 人事處 | E9: 移出 | F9: 2 | G9: 屆齡退休
A10: 3 | B10: 99 | C10: 99/06 | D10: 第一組 | E10: 新增 | F10: 3 | G10: 編制調整 | H10: 新增一個科室
A11: 4 | B11: 99 | C11: 99/09 | D11: 台北分局 | E11: 移入 | F11: 4 | G11: 業務移撥
A12: 5 | B12: 100 | C12: 100/02 | D12: 人事處 | E12: 移入 | F12: 2 | G12: 考試分發
A13: 6 | B13: 100 | C13: 100/05 | D13: 會計處 | E13: 減列 | F13: 1 | G13: 組織精簡
A14: 7 | B14: 100 | C14: 100/08 | D14: 第二組 | E14: 移出 | F14: 3 | G14: 業務移撥 | H14: 調至其他單位
A15: 8 | B15: 101 | C15: 101/03 | D15: 人事處 | E15: 精簡 | F15: 2 | G15: 優退
A16: 9 | B16: 101 | C16: 101/07 | D16: 新北分局 | E16: 新增 | F16: 5 | G16: 新設置 | H16: 新增分局
A17: 10 | B17: 102 | C17: 102/01 | D17: 政風處 | E17: 移入 | F17: 3 | G17: 業務調整
A18: 11 | B18: 103 | C18: 103/04 | D18: 第一組 | E18: 移出 | F18: 1 | G18: 屆齡退休
A19: 12 | B19: 104 | C19: 104/06 | D19: 人事處 | E19: 新增 | F19: 4 | G19: 編制調整 | H19: 業務擴張
A20: 13 | B20: 105 | C20: 105/02 | D20: 台北分局 | E20: 減列 | F20: 2 | G20: 組織整併

Sheet 05_篾選器
A1: 🔍 篩選查詢（使用 Ctrl+Shift+L 篩選）
A2: 【使用方法】
A3: 1. 選取任意資料格，按 Ctrl+Shift+L 開啟篩選
A4: 2. 可依「年度」「機關名稱」「調整類型」同時篩選
A5: 3. 要清除所有篩選：Ctrl+Shift+L → 清除
A6: 流水號 | B6: 年度 | C6: 修正日期 | D6: 機關名稱 | E6: 調整類型 | F6: 人數 | G6: 事由 | H6: 備註
A7: 1 | B7: 99 | C7: 99/01 | D7: 人事處 | E7: 移入 | F7: 5 | G7: 業務調整
A8: 2 | B8: 99 | C8: 99/03 | D8: 人事處 | E8: 移出 | F8: 2 | G8: 屆齡退休
A9: 3 | B9: 99 | C9: 99/06 | D9: 第一組 | E9: 新增 | F9: 3 | G9: 編制調整 | H9: 新增一個科室
A10: 4 | B10: 99 | C10: 99/09 | D10: 台北分局 | E10: 移入 | F10: 4 | G10: 業務移撥
A11: 5 | B11: 100 | C11: 100/02 | D11: 人事處 | E11: 移入 | F11: 2 | G11: 考試分發
A12: 6 | B12: 100 | C12: 100/05 | D12: 會計處 | E12: 減列 | F12: 1 | G12: 組織精簡
A13: 7 | B13: 100 | C13: 100/08 | D13: 第二組 | E13: 移出 | F13: 3 | G13: 業務移撥 | H13: 調至其他單位
A14: 8 | B14: 101 | C14: 101/03 | D14: 人事處 | E14: 精簡 | F14: 2 | G14: 優退
A15: 9 | B15: 101 | C15: 101/07 | D15: 新北分局 | E15: 新增 | F15: 5 | G15: 新設置 | H15: 新增分局
A16: 10 | B16: 102 | C16: 102/01 | D16: 政風處 | E16: 移入 | F16: 3 | G16: 業務調整
A17: 11 | B17: 103 | C17: 103/04 | D17: 第一組 | E17: 移出 | F17: 1 | G17: 屆齡退休
A18: 12 | B18: 104 | C18: 104/06 | D18: 人事處 | E18: 新增 | F18: 4 | G18: 編制調整 | H18: 業務擴張
A19: 13 | B19: 105 | C19: 105/02 | D19: 台北分局 | E19: 減列 | F19: 2 | G19: 組織整併

Sheet 06_使用手冊
A1: 📖 人事員額管理系統 使用手冊 v4（無代碼版）
A3: 【系統架構】
A5: 本系統包含 6 個工作表：
A7: 1️⃣ 00_機關清冊
A8: → 60個機關的基本資料（代碼+名稱）
A9: → 這是系統唯一定義處，下拉選單的來源
A10: → 新增/刪除機關在這裡處理
A12: 2️⃣ 01_異動主檔（主要輸入區）
A13: → 黃色格子可輸入｜下拉選單選擇
A14: → 這裡是唯一需要手動輸入資料的地方
A15: → 只有機關名稱，沒有代碼
A17: 3️⃣ 02_年初員額設定
... A94: v4（此版本）: 移除所有機關代碼欄位，只有名稱
